Workbook

Sheet Team_Inputs
A1: Team1 | B1: Team2 | C1: Team1H_A | D1: Team1Formation | E1: Team2Formation | F1: Win(3)_Draw(1)_Lose(0) | G1: Team1Player1 | H1: Team1Player2 | I1: Team1Player3 | J1: Team1Player4 | K1: Team1Player5 | L1: Team1Player6 | M1: Team1Player7 | N1: Team1Player8 | O1: Team1Player9 | P1: Team1Player10 | Q1: Team1Player11 | R1: Team2Player1 | S1: Team2Player2 | T1: Team2Player3 | U1: Team2Player4 | V1: Team2Player5 | W1: Team2Player6 | X1: Team2Player7 | Y1: Team2Player8 | Z1: Team2Player9 | AA1: Team2Player10 | AB1: Team2Player11 | AC1: Team1_Goals | AD1: Team2_Goals | AE1: Team1_BigChances | AF1: Team1_TotalShots | AG1: Team1_Corners | AH1: Team1_Passes | AI1: Team1_Tackels | AJ1: Team1_FreeKicks | AK1: Team1_BallPosses | AL1: Team2_BigChances | AM1: Team2_TotalShots | AN1: Team2_Corners | AO1: Team2_Passes | AP1: Team2_Tackels | AQ1: Team2_FreeKicks | AR1: Team2_BallPosses
A2: Fenerbahçe | B2: Çaykur Rizespor | C2: A | D2: 4-1-4-1 | E2: 4-2-3-1 | F2: 3 | G2: 6.2 | H2: 6 | I2: 7.1 | J2: 6.6 | K2: 6.4 | L2: 7.3 | M2: 7.4 | N2: 9 | O2: 7.2 | P2: 6.5 | Q2: 7.4 | R2: 7.2 | S2: 6 | T2: 5.7 | U2: 5.2 | V2: 6.3 | W2: 6.7 | X2: 6.2 | Y2: 6 | Z2: 6.4 | AA2: 6.6 | AB2: 7.2 | AC2: 5 | AD2: 2 | AE2: 5 | AF2: 28 | AG2: 9 | AH2: 457 | AI2: 15 | AJ2: 16 | AK2: 0.59 | AL2: 1 | AM2: 6 | AN2: 5 | AO2: 307 | AP2: 20 | AQ2: 6 | AR2: 0.41
A3: Fenerbahçe | B3: Kayserispor | C3: H | D3: 4-1-4-1 | E3: 4-1-4-1 | F3: 3 | G3: 6.9 | H3: 6.6 | I3: 6.5 | J3: 6.7 | K3: 6.8 | L3: 7.2 | M3: 8.7 | N3: 8 | O3: 8 | P3: 8.6 | Q3: 6.4 | R3: 6 | S3: 6 | T3: 6.9 | U3: 6 | V3: 6.3 | W3: 6.3 | X3: 6.4 | Y3: 6.2 | Z3: 6.5 | AA3: 6.9 | AB3: 8.3 | AC3: 4 | AD3: 2 | AE3: 5 | AF3: 28 | AG3: 8 | AH3: 532 | AI3: 14 | AJ3: 7 | AK3: 0.62 | AL3: 4 | AM3: 5 | AN3: 2 | AO3: 327 | AP3: 5 | AQ3: 13 | AR3: 0.38
A4: Fenerbahçe | B4: Viktoria Plzeň | C4: A | D4: 4-2-3-1 | E4: 3-4-1-2 | F4: 1 | G4: 8.8 | H4: 7.3 | I4: 8.3 | J4: 7.3 | K4: 7.3 | L4: 6.8 | M4: 6.7 | N4: 7 | O4: 7.1 | P4: 6.5 | Q4: 6.4 | R4: 8 | S4: 6.5 | T4: 7.6 | U4: 7.2 | V4: 6.7 | W4: 7 | X4: 6.6 | Y4: 6.9 | Z4: 6.7 | AA4: 6.1 | AB4: 6.4 | AC4: 0 | AD4: 0 | AE4: 2 | AF4: 10 | AG4: 2 | AH4: 447 | AI4: 27 | AJ4: 11 | AK4: 0.6 | AL4: 1 | AM4: 18 | AN4: 11 | AO4: 277 | AP4: 12 | AQ4: 7 | AR4: 0.4
A5: Fenerbahçe | B5: Beşiktaş JK | C5: A | D5: 4-1-4-1 | E5: 4-2-3-1 | F5: 3 | G5: 6.9 | H5: 6.2 | I5: 6.2 | J5: 7 | K5: 6.6 | L5: 7 | M5: 6.6 | N5: 7.6 | O5: 7.6 | P5: 5.9 | Q5: 6.1 | R5: 6.6 | S5: 7.3 | T5: 7 | U5: 7 | V5: 6.1 | W5: 6.2 | X5: 5.1 | Y5: 6.4 | Z5: 6.6 | AA5: 7 | AB5: 8.8 | AC5: 3 | AD5: 2 | AE5: 1 | AF5: 23 | AG5: 6 | AH5: 613 | AI5: 10 | AJ5: 8 | AK5: 0.68 | AL5: 1 | AM5: 9 | AN5: 1 | AO5: 277 | AP5: 15 | AQ5: 17 | AR5: 0.32
A6: Fenerbahçe | B6: Gaziantep FK | C6: A | D6: 4-1-4-1 | E6: 4-2-3-1 | F6: 3 | G6: 8.3 | H6: 7.5 | I6: 7.3 | J6: 7.4 | K6: 7.1 | L6: 6.6 | M6: 6.5 | N6: 6.6 | O6: 6.8 | P6: 6.2 | Q6: 8.3 | R6: 6.9 | S6: 6.3 | T6: 6.4 | U6: 6.1 | V6: 6.2 | W6: 6.3 | X6: 6.8 | Y6: 6.3 | Z6: 6.3 | AA6: 5.5 | AB6: 7 | AC6: 4 | AD6: 0 | AE6: 7 | AF6: 20 | AG6: 4 | AH6: 295 | AI6: 31 | AJ6: 12 | AK6: 0.41 | AL6: 1 | AM6: 8 | AN6: 6 | AO6: 423 | AP6: 12 | AQ6: 15 | AR6: 0.59
A7: Fenerbahçe | B7: VfB Stuttgart | C7: H | D7: 4-3-3 | E7: 3-4-2-1 | F7: 3 | G7: 7 | H7: 6.8 | I7: 8 | J7: 6.8 | K7: 6.8 | L7: 6.9 | M7: 6.6 | N7: 6.6 | O7: 7 | P7: 6.1 | Q7: 7.7 | R7: 7.8 | S7: 6.8 | T7: 7.3 | U7: 6.8 | V7: 6.5 | W7: 6.8 | X7: 7.1 | Y7: 6.9 | Z7: 6.5 | AA7: 6.5 | AB7: 6.7 | AC7: 1 | AD7: 0 | AE7: 1 | AF7: 19 | AG7: 4 | AH7: 261 | AI7: 12 | AJ7: 14 | AK7: 0.35 | AL7: 1 | AM7: 12 | AN7: 7 | AO7: 486 | AP7: 11 | AQ7: 11 | AR7: 0.65
A8: Fenerbahçe | B8: Fatih Karagümrük | C8: H | D8: 4-3-3 | E8: 4-2-3-1 | F8: 3 | G8: 7.5 | H8: 7 | I8: 7.2 | J8: 6.8 | K8: 6.8 | L8: 7.4 | M8: 6.6 | N8: 7.5 | O8: 6.9 | P8: 6.8 | Q8: 8.2 | R8: 7.1 | S8: 6.6 | T8: 6.1 | U8: 6.5 | V8: 5.4 | W8: 6.5 | X8: 6.4 | Y8: 7.1 | Z8: 6.7 | AA8: 6.7 | AB8: 6.5 | AC8: 2 | AD8: 1 | AE8: 3 | AF8: 21 | AG8: 6 | AH8: 448 | AI8: 24 | AJ8: 18 | AK8: 0.59 | AL8: 1 | AM8: 16 | AN8: 6 | AO8: 311 | AP8: 17 | AQ8: 10 | AR8: 0.41
A9: Fenerbahçe | B9: Samsunspor | C9: A | D9: 4-1-4-1 | E9: 4-1-4-1 | F9: 1 | G9: 7.4 | H9: 7.3 | I9: 7.3 | J9: 6.8 | K9: 7.1 | L9: 7.1 | M9: 6.6 | N9: 6.8 | O9: 6.6 | P9: 6.4 | Q9: 6.5 | R9: 7.2 | S9: 7 | T9: 6.8 | U9: 7.2 | V9: 7.1 | W9: 6.9 | X9: 6.6 | Y9: 6.5 | Z9: 7.3 | AA9: 7.4 | AB9: 6.4 | AC9: 0 | AD9: 0 | AE9: 0 | AF9: 6 | AG9: 5 | AH9: 422 | AI9: 14 | AJ9: 13 | AK9: 0.53 | AL9: 4 | AM9: 12 | AN9: 6 | AO9: 373 | AP9: 15 | AQ9: 15 | AR9: 0.47
A10: Fenerbahçe | B10: Nice | C10: H | D10: 4-3-3 | E10: 4-3-3 | F10: 3 | G10: 6.5 | H10: 6.6 | I10: 6.7 | J10: 7.5 | K10: 6.6 | L10: 7.1 | M10: 7 | N10: 6.2 | O10: 6.8 | P10: 6.9 | Q10: 9.4 | R10: 6.5 | S10: 5.8 | T10: 6.6 | U10: 6.2 | V10: 6.7 | W10: 6.7 | X10: 6.2 | Y10: 6.4 | Z10: 6.6 | AA10: 6.8 | AB10: 7 | AC10: 2 | AD10: 1 | AE10: 2 | AF10: 17 | AG10: 3 | AH10: 498 | AI10: 23 | AJ10: 17 | AK10: 0.59 | AL10: 2 | AM10: 10 | AN10: 4 | AO10: 341 | AP10: 13 | AQ10: 11 | AR10: 0.41
A11: Fenerbahçe | B11: Antalyaspor | C11: H | D11: 4-2-3-1 | E11: 4-2-3-1 | F11: 3 | G11: 6.9 | H11: 7.4 | I11: 7.5 | J11: 7.2 | K11: 7.2 | L11: 6.6 | M11: 7.9 | N11: 7.9 | O11: 6.9 | P11: 6.7 | Q11: 6.9 | R11: 8.7 | S11: 6.8 | T11: 6.5 | U11: 6.5 | V11: 5.4 | W11: 6.5 | X11: 6 | Y11: 6.5 | Z11: 6.4 | AA11: 6.5 | AB11: 6.8 | AC11: 2 | AD11: 0 | AE11: 4 | AF11: 19 | AG11: 5 | AH11: 567 | AI11: 24 | AJ11: 13 | AK11: 0.67 | AL11: 1 | AM11: 4 | AN11: 3 | AO11: 292 | AP11: 16 | AQ11: 19 | AR11: 0.33
A12: Fenerbahçe | B12: GNK Dinamo Zagreb | C12: A | D12: 3-4-2-1 | E12: 4-1-4-1 | F12: 0 | G12: 6 | H12: 6.7 | I12: 6.7 | J12: 5.9 | K12: 6.2 | L12: 6.7 | M12: 6.2 | N12: 5.9 | O12: 7.3 | P12: 6.6 | Q12: 6.3 | R12: 6 | S12: 7.3 | T12: 6.7 | U12: 7 | V12: 7.3 | W12: 7.7 | X12: 6.8 | Y12: 6.7 | Z12: 6.5 | AA12: 8.1 | AB12: 8.3 | AC12: 1 | AD12: 3 | AE12: 0 | AF12: 6 | AG12: 6 | AH12: 524 | AI12: 15 | AJ12: 7 | AK12: 0.58 | AL12: 2 | AM12: 11 | AN12: 5 | AO12: 378 | AP12: 24 | AQ12: 8 | AR12: 0.42
A13: Fenerbahçe | B13: Kasımpaşa | C13: A | D13: 4-2-3-1 | E13: 4-1-4-1 | F13: 1 | G13: 7.1 | H13: 7.2 | I13: 7.7 | J13: 7.2 | K13: 6.5 | L13: 6.5 | M13: 7 | N13: 6.5 | O13: 6.9 | P13: 6.8 | Q13: 6.3 | R13: 5.6 | S13: 6.5 | T13: 6.9 | U13: 7 | V13: 7.4 | W13: 7.3 | X13: 7.3 | Y13: 7.7 | Z13: 5.5 | AA13: 6.4 | AB13: 6.3 | AC13: 1 | AD13: 1 | AE13: 2 | AF13: 9 | AG13: 8 | AH13: 551 | AI13: 20 | AJ13: 11 | AK13: 0.66 | AL13: 2 | AM13: 17 | AN13: 5 | AO13: 280 | AP13: 19 | AQ13: 15 | AR13: 0.34
... A42: Fenerbahçe | B42: Alanyaspor | C42: A | D42: 3-4-1-2 | E42: 4-2-3-1 | F42: 3 | G42: 7.5 | H42: 7 | I42: 6.7 | J42: 7.2 | K42: 6.9 | L42: 7.7 | M42: 7.2 | N42: 7.1 | O42: 7.1 | P42: 7.3 | Q42: 7 | R42: 6.9 | S42: 7.3 | T42: 6.8 | U42: 7.4 | V42: 6.5 | W42: 7 | X42: 6.1 | Y42: 7.1 | Z42: 7 | AA42: 6.4 | AB42: 6.8 | AC42: 2 | AD42: 0 | AE42: 3 | AF42: 8 | AG42: 3 | AH42: 440 | AI42: 14 | AJ42: 17 | AK42: 0.47 | AL42: 3 | AM42: 12 | AN42: 2 | AO42: 486 | AP42: 13 | AQ42: 13 | AR42: 0.53

Sheet Team_Test
A1: Team1 | B1: Team2 | C1: Team1H_A | D1: Team1Formation | E1: Team2Formation | F1: Team1Player1 | G1: Team1Player2 | H1: Team1Player3 | I1: Team1Player4 | J1: Team1Player5 | K1: Team1Player6 | L1: Team1Player7 | M1: Team1Player8 | N1: Team1Player9 | O1: Team1Player10 | P1: Team1Player11 | Q1: Team2Player1 | R1: Team2Player2 | S1: Team2Player3 | T1: Team2Player4 | U1: Team2Player5 | V1: Team2Player6 | W1: Team2Player7 | X1: Team2Player8 | Y1: Team2Player9 | Z1: Team2Player10 | AA1: Team2Player11
A2: Fenerbahçe | B2: Ferencváros TC | C2: Home | D2: 4-2-3-1 | E2: 4-2-3-1 | F2: 7.98 | G2: 6.51 | H2: 5.76 | I2: 5.77 | J2: 6.86 | K2: 6.79 | L2: 7.7 | M2: 6.87 | N2: 7.71 | O2: 5.5 | P2: 7.34 | Q2: =_xlfn.NORM.INV(RAND(),AVERAGE(6.57,7.09,7.09,6.93,7.31,6.89,6.74), STDEV(6.57,7.09,7.09,6.93,7.31,6.89,6.74)) -> 6.8978509 | R2: =_xlfn.NORM.INV(RAND(),AVERAGE(6.57,7.09,7.09,6.93,7.31,6.89,6.74), STDEV(6.57,7.09,7.09,6.93,7.31,6.89,6.74)) -> 6.9006835 | S2: =_xlfn.NORM.INV(RAND(),AVERAGE(6.57,7.09,7.09,6.93,7.31,6.89,6.74), STDEV(6.57,7.09,7.09,6.93,7.31,6.89,6.74)) -> 6.6382248 | T2: =_xlfn.NORM.INV(RAND(),AVERAGE(6.57,7.09,7.09,6.93,7.31,6.89,6.74), STDEV(6.57,7.09,7.09,6.93,7.31,6.89,6.74)) -> 6.9485537 | U2: =_xlfn.NORM.INV(RAND(),AVERAGE(6.57,7.09,7.09,6.93,7.31,6.89,6.74), STDEV(6.57,7.09,7.09,6.93,7.31,6.89,6.74)) -> 6.8984897 | V2: =_xlfn.NORM.INV(RAND(),AVERAGE(6.57,7.09,7.09,6.93,7.31,6.89,6.74), STDEV(6.57,7.09,7.09,6.93,7.31,6.89,6.74)) -> 6.8879306 | W2: =_xlfn.NORM.INV(RAND(),AVERAGE(6.57,7.09,7.09,6.93,7.31,6.89,6.74), STDEV(6.57,7.09,7.09,6.93,7.31,6.89,6.74)) -> 6.9615726 | X2: =_xlfn.NORM.INV(RAND(),AVERAGE(6.57,7.09,7.09,6.93,7.31,6.89,6.74), STDEV(6.57,7.09,7.09,6.93,7.31,6.89,6.74)) -> 7.2292048 | ... AA2: =_xlfn.NORM.INV(RAND(),AVERAGE(6.57,7.09,7.09,6.93,7.31,6.89,6.74), STDEV(6.57,7.09,7.09,6.93,7.31,6.89,6.74)) -> 6.8526333
A3: Fenerbahçe | B3: Galatasaray | C3: Home | D3: 4-2-3-1 | E3: 4-2-3-1 | F3: 7.62 | G3: 6.98 | H3: 6.65 | I3: 7.22 | J3: 6.93 | K3: 7.37 | L3: 7.34 | M3: 6.07 | N3: 7.4 | O3: 7.26 | P3: 7.67 | Q3: =_xlfn.NORM.INV(RAND(),6.91, 0.24) -> 6.7431689 | R3: =_xlfn.NORM.INV(RAND(),6.91, 0.24) -> 7.31212 | S3: =_xlfn.NORM.INV(RAND(),6.91, 0.24) -> 6.6655299 | T3: =_xlfn.NORM.INV(RAND(),6.91, 0.24) -> 6.6722945 | U3: =_xlfn.NORM.INV(RAND(),6.91, 0.24) -> 6.4918361 | V3: =_xlfn.NORM.INV(RAND(),6.91, 0.24) -> 6.5204133 | W3: =_xlfn.NORM.INV(RAND(),6.91, 0.24) -> 6.9733697 | X3: =_xlfn.NORM.INV(RAND(),6.91, 0.24) -> 6.9520224 | ... AA3: =_xlfn.NORM.INV(RAND(),6.91, 0.24) -> 6.3806999
A4: Fenerbahçe | B4: Galatasaray | C4: Home | D4: 4-2-3-1 | E4: 4-2-3-1 | F4: 7.51 | G4: 7.59 | H4: 7.21 | I4: 7.54 | J4: 6.86 | K4: 6.99 | L4: 7.48 | M4: 7.15 | N4: 6.78 | O4: 5.67 | P4: 6.24 | Q4: =_xlfn.NORM.INV(RAND(),6.91, 0.24) -> 6.708214 | R4: =_xlfn.NORM.INV(RAND(),6.91, 0.24) -> 6.7626984 | S4: =_xlfn.NORM.INV(RAND(),6.91, 0.24) -> 6.5860948 | T4: =_xlfn.NORM.INV(RAND(),6.91, 0.24) -> 6.8051161 | U4: =_xlfn.NORM.INV(RAND(),6.91, 0.24) -> 6.9810203 | V4: =_xlfn.NORM.INV(RAND(),6.91, 0.24) -> 6.6056565 | W4: =_xlfn.NORM.INV(RAND(),6.91, 0.24) -> 6.8987811 | X4: =_xlfn.NORM.INV(RAND(),6.91, 0.24) -> 6.6321741 | ... AA4: =_xlfn.NORM.INV(RAND(),6.91, 0.24) -> 7.3885586
A5: Fenerbahçe | B5: Galatasaray | C5: Home | D5: 4-2-3-1 | E5: 4-2-3-1 | F5: 7.77 | G5: 6.36 | H5: 6.48 | I5: 6.9 | J5: 6.61 | K5: 6.51 | L5: 6.86 | M5: 7.36 | N5: 6.63 | O5: 6.52 | P5: 8.58 | Q5: =_xlfn.NORM.INV(RAND(),6.91, 0.24) -> 7.0244104 | R5: =_xlfn.NORM.INV(RAND(),6.91, 0.24) -> 6.7702004 | S5: =_xlfn.NORM.INV(RAND(),6.91, 0.24) -> 7.4771462 | T5: =_xlfn.NORM.INV(RAND(),6.91, 0.24) -> 7.0480475 | U5: =_xlfn.NORM.INV(RAND(),6.91, 0.24) -> 7.1651162 | V5: =_xlfn.NORM.INV(RAND(),6.91, 0.24) -> 6.9217771 | W5: =_xlfn.NORM.INV(RAND(),6.91, 0.24) -> 7.3350466 | X5: =_xlfn.NORM.INV(RAND(),6.91, 0.24) -> 6.9662108 | ... AA5: =_xlfn.NORM.INV(RAND(),6.91, 0.24) -> 7.1215424
A6: Fenerbahçe | B6: Galatasaray | C6: Home | D6: 4-2-3-1 | E6: 4-2-3-1 | F6: 7.66 | G6: 6.86 | H6: 6.67 | I6: 6.43 | J6: 7.19 | K6: 7.11 | L6: 5.65 | M6: 7.45 | N6: 6.49 | O6: 6.95 | P6: 4.47 | Q6: =_xlfn.NORM.INV(RAND(),6.91, 0.24) -> 6.9850056 | R6: =_xlfn.NORM.INV(RAND(),6.91, 0.24) -> 7.0591674 | S6: =_xlfn.NORM.INV(RAND(),6.91, 0.24) -> 6.7037494 | T6: =_xlfn.NORM.INV(RAND(),6.91, 0.24) -> 6.6981458 | U6: =_xlfn.NORM.INV(RAND(),6.91, 0.24) -> 7.3046964 | V6: =_xlfn.NORM.INV(RAND(),6.91, 0.24) -> 7.3626467 | W6: =_xlfn.NORM.INV(RAND(),6.91, 0.24) -> 6.4546643 | X6: =_xlfn.NORM.INV(RAND(),6.91, 0.24) -> 6.6250893 | ... AA6: =_xlfn.NORM.INV(RAND(),6.91, 0.24) -> 7.0173448
A7: Fenerbahçe | B7: Galatasaray | C7: Home | D7: 4-2-3-1 | E7: 4-2-3-1 | F7: 7.55 | G7: 6.35 | H7: 7.64 | I7: 7.07 | J7: 6.96 | K7: 5.91 | L7: 5.42 | M7: 7.55 | N7: 7.9 | O7: 6 | P7: 7.05 | Q7: =_xlfn.NORM.INV(RAND(),6.91, 0.24) -> 7.0247824 | R7: =_xlfn.NORM.INV(RAND(),6.91, 0.24) -> 6.9450668 | S7: =_xlfn.NORM.INV(RAND(),6.91, 0.24) -> 6.6767763 | T7: =_xlfn.NORM.INV(RAND(),6.91, 0.24) -> 7.0265706 | U7: =_xlfn.NORM.INV(RAND(),6.91, 0.24) -> 7.1869853 | V7: =_xlfn.NORM.INV(RAND(),6.91, 0.24) -> 6.8670421 | W7: =_xlfn.NORM.INV(RAND(),6.91, 0.24) -> 7.0158545 | X7: =_xlfn.NORM.INV(RAND(),6.91, 0.24) -> 6.9705222 | ... AA7: =_xlfn.NORM.INV(RAND(),6.91, 0.24) -> 7.1681616
A8: Fenerbahçe | B8: Galatasaray | C8: Home | D8: 4-2-3-1 | E8: 4-2-3-1 | F8: 5.84 | G8: 6.83 | H8: 7.33 | I8: 6.52 | J8: 7.27 | K8: 7.16 | L8: 6.21 | M8: 6.26 | N8: 6.48 | O8: 6.32 | P8: 8.88 | Q8: =_xlfn.NORM.INV(RAND(),6.91, 0.24) -> 6.8614585 | R8: =_xlfn.NORM.INV(RAND(),6.91, 0.24) -> 6.4154011 | S8: =_xlfn.NORM.INV(RAND(),6.91, 0.24) -> 7.1294466 | T8: =_xlfn.NORM.INV(RAND(),6.91, 0.24) -> 7.0543133 | U8: =_xlfn.NORM.INV(RAND(),6.91, 0.24) -> 6.9706084 | V8: =_xlfn.NORM.INV(RAND(),6.91, 0.24) -> 6.7997802 | W8: =_xlfn.NORM.INV(RAND(),6.91, 0.24) -> 6.8145326 | X8: =_xlfn.NORM.INV(RAND(),6.91, 0.24) -> 6.650661 | ... AA8: =_xlfn.NORM.INV(RAND(),6.91, 0.24) -> 6.6595613
A9: Fenerbahçe | B9: Galatasaray | C9: Home | D9: 4-2-3-1 | E9: 4-2-3-1 | F9: 7.39 | G9: 7.15 | H9: 6.43 | I9: 6.96 | J9: 6.54 | K9: 7.06 | L9: 5.05 | M9: 7.94 | N9: 6.88 | O9: 6.78 | P9: 7.48 | Q9: =_xlfn.NORM.INV(RAND(),6.91, 0.24) -> 6.805884 | R9: =_xlfn.NORM.INV(RAND(),6.91, 0.24) -> 6.9265637 | S9: =_xlfn.NORM.INV(RAND(),6.91, 0.24) -> 6.4887763 | T9: =_xlfn.NORM.INV(RAND(),6.91, 0.24) -> 6.4834417 | U9: =_xlfn.NORM.INV(RAND(),6.91, 0.24) -> 6.9811053 | V9: =_xlfn.NORM.INV(RAND(),6.91, 0.24) -> 6.6941165 | W9: =_xlfn.NORM.INV(RAND(),6.91, 0.24) -> 7.1018303 | X9: =_xlfn.NORM.INV(RAND(),6.91, 0.24) -> 6.3594399 | ... AA9: =_xlfn.NORM.INV(RAND(),6.91, 0.24) -> 7.1470204
A10: Fenerbahçe | B10: Galatasaray | C10: Home | D10: 4-2-3-1 | E10: 4-2-3-1 | F10: 8.5 | G10: 7.22 | H10: 7.79 | I10: 7.8 | J10: 6.93 | K10: 7.11 | L10: 7.16 | M10: 6.96 | N10: 6.53 | O10: 5.86 | P10: 5.49 | Q10: =_xlfn.NORM.INV(RAND(),6.91, 0.24) -> 6.5754456 | R10: =_xlfn.NORM.INV(RAND(),6.91, 0.24) -> 6.9850177 | S10: =_xlfn.NORM.INV(RAND(),6.91, 0.24) -> 7.3520672 | T10: =_xlfn.NORM.INV(RAND(),6.91, 0.24) -> 7.1114992 | U10: =_xlfn.NORM.INV(RAND(),6.91, 0.24) -> 7.011131 | V10: =_xlfn.NORM.INV(RAND(),6.91, 0.24) -> 6.8013322 | W10: =_xlfn.NORM.INV(RAND(),6.91, 0.24) -> 6.9979944 | X10: =_xlfn.NORM.INV(RAND(),6.91, 0.24) -> 6.8566001 | ... AA10: =_xlfn.NORM.INV(RAND(),6.91, 0.24) -> 7.3401788
A11: Fenerbahçe | B11: Galatasaray | C11: Home | D11: 4-2-3-1 | E11: 4-2-3-1 | F11: 7.12 | G11: 6.55 | H11: 7 | I11: 6.82 | J11: 6.6 | K11: 6.92 | L11: 7.05 | M11: 6.17 | N11: 6.68 | O11: 7.71 | P11: 7.15 | Q11: =_xlfn.NORM.INV(RAND(),6.91, 0.24) -> 6.5744954 | R11: =_xlfn.NORM.INV(RAND(),6.91, 0.24) -> 6.5874636 | S11: =_xlfn.NORM.INV(RAND(),6.91, 0.24) -> 7.2344724 | T11: =_xlfn.NORM.INV(RAND(),6.91, 0.24) -> 6.5558818 | U11: =_xlfn.NORM.INV(RAND(),6.91, 0.24) -> 6.6771035 | V11: =_xlfn.NORM.INV(RAND(),6.91, 0.24) -> 6.9554295 | W11: =_xlfn.NORM.INV(RAND(),6.91, 0.24) -> 6.8848178 | X11: =_xlfn.NORM.INV(RAND(),6.91, 0.24) -> 6.9929297 | ... AA11: =_xlfn.NORM.INV(RAND(),6.91, 0.24) -> 7.0968039
A12: Fenerbahçe | B12: Galatasaray | C12: Home | D12: 4-2-3-1 | E12: 4-2-3-1 | F12: 8.18 | G12: 6.47 | H12: 7.16 | I12: 6.95 | J12: 6.9 | K12: 6.79 | L12: 6.76 | M12: 5.64 | N12: 7.35 | O12: 6.05 | P12: 9.32 | Q12: =_xlfn.NORM.INV(RAND(),6.91, 0.24) -> 6.872173 | R12: =_xlfn.NORM.INV(RAND(),6.91, 0.24) -> 7.0987282 | S12: =_xlfn.NORM.INV(RAND(),6.91, 0.24) -> 7.3176363 | T12: =_xlfn.NORM.INV(RAND(),6.91, 0.24) -> 6.6195214 | U12: =_xlfn.NORM.INV(RAND(),6.91, 0.24) -> 6.7229522 | V12: =_xlfn.NORM.INV(RAND(),6.91, 0.24) -> 6.8324645 | W12: =_xlfn.NORM.INV(RAND(),6.91, 0.24) -> 6.9899024 | X12: =_xlfn.NORM.INV(RAND(),6.91, 0.24) -> 6.9089423 | ... AA12: =_xlfn.NORM.INV(RAND(),6.91, 0.24) -> 6.7051724
A13: Fenerbahçe | B13: Galatasaray | C13: Home | D13: 4-2-3-1 | E13: 4-2-3-1 | F13: 6.39 | G13: 7 | H13: 7.07 | I13: 7.31 | J13: 6.72 | K13: 6.86 | L13: 5.57 | M13: 7.15 | N13: 6.72 | O13: 6.55 | P13: 6.91 | Q13: =_xlfn.NORM.INV(RAND(),6.91, 0.24) -> 7.6408981 | R13: =_xlfn.NORM.INV(RAND(),6.91, 0.24) -> 7.1066212 | S13: =_xlfn.NORM.INV(RAND(),6.91, 0.24) -> 7.3166999 | T13: =_xlfn.NORM.INV(RAND(),6.91, 0.24) -> 6.6902844 | U13: =_xlfn.NORM.INV(RAND(),6.91, 0.24) -> 6.7704263 | V13: =_xlfn.NORM.INV(RAND(),6.91, 0.24) -> 7.2629512 | W13: =_xlfn.NORM.INV(RAND(),6.91, 0.24) -> 6.8877983 | X13: =_xlfn.NORM.INV(RAND(),6.91, 0.24) -> 7.1519098 | ... AA13: =_xlfn.NORM.INV(RAND(),6.91, 0.24) -> 7.1881961
A14: Fenerbahçe | B14: Galatasaray | C14: Home | D14: 4-2-3-1 | E14: 4-2-3-1 | F14: 7.53 | G14: 7.32 | H14: 7.96 | I14: 7.43 | J14: 6.9 | K14: 6.77 | L14: 7.9 | M14: 6.97 | N14: 7.25 | O14: 4.61 | P14: 9.18 | Q14: =_xlfn.NORM.INV(RAND(),6.91, 0.24) -> 7.0494569 | R14: =_xlfn.NORM.INV(RAND(),6.91, 0.24) -> 6.6688676 | S14: =_xlfn.NORM.INV(RAND(),6.91, 0.24) -> 6.874262 | T14: =_xlfn.NORM.INV(RAND(),6.91, 0.24) -> 6.6146671 | U14: =_xlfn.NORM.INV(RAND(),6.91, 0.24) -> 7.4752445 | V14: =_xlfn.NORM.INV(RAND(),6.91, 0.24) -> 6.9114854 | W14: =_xlfn.NORM.INV(RAND(),6.91, 0.24) -> 7.0682892 | X14: =_xlfn.NORM.INV(RAND(),6.91, 0.24) -> 6.836692 | ... AA14: =_xlfn.NORM.INV(RAND(),6.91, 0.24) -> 7.2811594
... A1801: Fenerbahçe | B1801: Galatasaray | C1801: Home | D1801: 4-3-3 | E1801: 4-3-3 | F1801: 9.07 | G1801: 6.68 | H1801: 6.42 | I1801: 7.16 | J1801: 6.55 | K1801: 7.18 | L1801: 8.09 | M1801: 7.69 | N1801: 7.32 | O1801: 5.68 | P1801: 8.24 | Q1801: =_xlfn.NORM.INV(RAND(),6.91, 0.24) -> 6.5539946 | R1801: =_xlfn.NORM.INV(RAND(),6.91, 0.24) -> 6.9062195 | S1801: =_xlfn.NORM.INV(RAND(),6.91, 0.24) -> 6.9800436 | T1801: =_xlfn.NORM.INV(RAND(),6.91, 0.24) -> 6.8192588 | U1801: =_xlfn.NORM.INV(RAND(),6.91, 0.24) -> 6.7277127 | V1801: =_xlfn.NORM.INV(RAND(),6.91, 0.24) -> 6.9869536 | W1801: =_xlfn.NORM.INV(RAND(),6.91, 0.24) -> 7.2170958 | X1801: =_xlfn.NORM.INV(RAND(),6.91, 0.24) -> 6.9771064 | ... AA1801: =_xlfn.NORM.INV(RAND(),6.91, 0.24) -> 6.8741995

Sheet clusters
D6: 1 | E6: 2 | F6: 3 | G6: 4 | H6: 5 | K6: 1 | L6: 2 | M6: 3 | N6: 4 | O6: 5
C7: 1 | J7: 1
C8: 2 | E8: x | J8: 2 | L8: x
C9: 3 | G9: x | J9: 3 | N9: x
C10: 4 | E10: x | F10: x | J10: 4 | L10: x | M10: x
C11: 5 | D11: p1 | G11: x | H11: x | J11: 5 | K11: p1 | N11: x | O11: x
C12: 6 | E12: x | F12: x | J12: 6 | L12: x | M12: x
C13: 7 | G13: x | J13: 7 | N13: x
C14: 8 | E14: x | J14: 8 | L14: x
C15: 9 | J15: 9
D24: 1 | E24: 2 | F24: 3 | G24: 4 | H24: 5 | K24: 1 | L24: 2 | M24: 3 | N24: 4 | O24: 5
C25: 1 | J25: 1
C26: 2 | F26: x | J26: 2 | L26: x
C27: 3 | E27: x | J27: 3 | N27: x
C28: 4 | F28: x | G28: x | J28: 4 | L28: x | M28: x
C29: 5 | D29: p1 | E29: x | H29: x | J29: 5 | K29: p1 | N29: x | O29: x
C30: 6 | F30: x | G30: x | J30: 6 | L30: x | M30: x
C31: 7 | E31: x | J31: 7 | N31: x
C32: 8 | F32: x | J32: 8 | L32: x
C33: 9 | J33: 9

Sheet Team_Test (2)
A1: Team1 | B1: Team2 | C1: Team1H_A | D1: Team1Formation | E1: Team2Formation | F1: Opponent_Tier | G1: Win(3)_Draw(1)_Lose(0) | H1: Team1Player1 | I1: Team1Player2 | J1: Team1Player3 | K1: Team1Player4 | L1: Team1Player5 | M1: Team1Player6 | N1: Team1Player7 | O1: Team1Player8 | P1: Team1Player9 | Q1: Team1Player10 | R1: Team1Player11 | S1: Team2Player1 | T1: Team2Player2 | U1: Team2Player3 | V1: Team2Player4 | W1: Team2Player5 | X1: Team2Player6 | Y1: Team2Player7 | Z1: Team2Player8 | AA1: Team2Player9 | AB1: Team2Player10 | AC1: Team2Player11 | AD1: Team1_Goals | AE1: Team2_Goals | AF1: Team1_BigChances | AG1: Team1_TotalShots | AH1: Team1_Corners | AI1: Team1_Passes | AJ1: Team1_Tackels | AK1: Team1_FreeKicks | AL1: Team1_BallPosses | AM1: Team2_BigChances | AN1: Team2_TotalShots | AO1: Team2_Corners | AP1: Team2_Passes | AQ1: Team2_Tackels | AR1: Team2_FreeKicks | AS1: Team2_BallPosses
A2: Fenerbahçe | B2: Beşiktaş | C2: Away | D2: 4-2-3-1 | E2: 4-2-3-1 | F2: =VLOOKUP(B2,Sheet2!A:E,5,0) -> 4 | H2: =ROUND(_xlfn.NORM.INV(RAND(),AVERAGE(Team_Inputs!#REF!),STDEV(Team_Inputs!#REF!)),2) -> #REF! | I2: =ROUND(_xlfn.NORM.INV(RAND(),AVERAGE(Team_Inputs!#REF!),STDEV(Team_Inputs!#REF!)),2) -> #REF! | J2: =ROUND(_xlfn.NORM.INV(RAND(),AVERAGE(Team_Inputs!#REF!),STDEV(Team_Inputs!#REF!)),2) -> #REF! | K2: =ROUND(_xlfn.NORM.INV(RAND(),AVERAGE(Team_Inputs!#REF!),STDEV(Team_Inputs!#REF!)),2) -> #REF! | L2: =ROUND(_xlfn.NORM.INV(RAND(),AVERAGE(Team_Inputs!#REF!),STDEV(Team_Inputs!#REF!)),2) -> #REF! | M2: =ROUND(_xlfn.NORM.INV(RAND(),AVERAGE(Team_Inputs!#REF!),STDEV(Team_Inputs!#REF!)),2) -> #REF! | N2: =ROUND(_xlfn.NORM.INV(RAND(),AVERAGE(Team_Inputs!#REF!),STDEV(Team_Inputs!#REF!)),2) -> #REF! | O2: =ROUND(_xlfn.NORM.INV(RAND(),AVERAGE(Team_Inputs!#REF!),STDEV(Team_Inputs!#REF!)),2) -> #REF! | ... R2: =ROUND(_xlfn.NORM.INV(RAND(),AVERAGE(Team_Inputs!#REF!),STDEV(Team_Inputs!#REF!)),2) -> #REF! | S2: =ROUND(_xlfn.NORM.INV(RAND(),AVERAGE([1]Team_Inputs!$H$2:$H$15),STDEV([1]Team_Inputs!$H$2:$H$15)),2) -> 4.97 | T2: =ROUND(_xlfn.NORM.INV(RAND(),AVERAGE([1]Team_Inputs!$H$2:$H$15),STDEV([1]Team_Inputs!$H$2:$H$15)),2) -> 6.8 | U2: =ROUND(_xlfn.NORM.INV(RAND(),AVERAGE([1]Team_Inputs!$H$2:$H$15),STDEV([1]Team_Inputs!$H$2:$H$15)),2) -> 6.27 | V2: =ROUND(_xlfn.NORM.INV(RAND(),AVERAGE([1]Team_Inputs!$H$2:$H$15),STDEV([1]Team_Inputs!$H$2:$H$15)),2) -> 6.13 | W2: =ROUND(_xlfn.NORM.INV(RAND(),AVERAGE([1]Team_Inputs!$H$2:$H$15),STDEV([1]Team_Inputs!$H$2:$H$15)),2) -> 6.74 | X2: =ROUND(_xlfn.NORM.INV(RAND(),AVERAGE([1]Team_Inputs!$H$2:$H$15),STDEV([1]Team_Inputs!$H$2:$H$15)),2) -> 6.1 | Y2: =ROUND(_xlfn.NORM.INV(RAND(),AVERAGE([1]Team_Inputs!$H$2:$H$15),STDEV([1]Team_Inputs!$H$2:$H$15)),2) -> 7.26 | Z2: =ROUND(_xlfn.NORM.INV(RAND(),AVERAGE([1]Team_Inputs!$H$2:$H$15),STDEV([1]Team_Inputs!$H$2:$H$15)),2) -> 7.26 | ... AC2: =ROUND(_xlfn.NORM.INV(RAND(),AVERAGE([1]Team_Inputs!$H$2:$H$15),STDEV([1]Team_Inputs!$H$2:$H$15)),2) -> 6.37
A3: Fenerbahçe | B3: Beşiktaş | C3: Away | D3: 4-2-3-1 | E3: 4-2-3-1 | F3: =VLOOKUP(B3,Sheet2!A:E,5,0) -> 4 | H3: =ROUND(_xlfn.NORM.INV(RAND(),AVERAGE(Team_Inputs!#REF!),STDEV(Team_Inputs!#REF!)),2) -> #REF! | I3: =ROUND(_xlfn.NORM.INV(RAND(),AVERAGE(Team_Inputs!#REF!),STDEV(Team_Inputs!#REF!)),2) -> #REF! | J3: =ROUND(_xlfn.NORM.INV(RAND(),AVERAGE(Team_Inputs!#REF!),STDEV(Team_Inputs!#REF!)),2) -> #REF! | K3: =ROUND(_xlfn.NORM.INV(RAND(),AVERAGE(Team_Inputs!#REF!),STDEV(Team_Inputs!#REF!)),2) -> #REF! | L3: =ROUND(_xlfn.NORM.INV(RAND(),AVERAGE(Team_Inputs!#REF!),STDEV(Team_Inputs!#REF!)),2) -> #REF! | M3: =ROUND(_xlfn.NORM.INV(RAND(),AVERAGE(Team_Inputs!#REF!),STDEV(Team_Inputs!#REF!)),2) -> #REF! | N3: =ROUND(_xlfn.NORM.INV(RAND(),AVERAGE(Team_Inputs!#REF!),STDEV(Team_Inputs!#REF!)),2) -> #REF! | O3: =ROUND(_xlfn.NORM.INV(RAND(),AVERAGE(Team_Inputs!#REF!),STDEV(Team_Inputs!#REF!)),2) -> #REF! | ... R3: =ROUND(_xlfn.NORM.INV(RAND(),AVERAGE(Team_Inputs!#REF!),STDEV(Team_Inputs!#REF!)),2) -> #REF! | S3: =ROUND(_xlfn.NORM.INV(RAND(),AVERAGE([1]Team_Inputs!$H$2:$H$15),STDEV([1]Team_Inputs!$H$2:$H$15)),2) -> 5 | T3: =ROUND(_xlfn.NORM.INV(RAND(),AVERAGE([1]Team_Inputs!$H$2:$H$15),STDEV([1]Team_Inputs!$H$2:$H$15)),2) -> 7.02 | U3: =ROUND(_xlfn.NORM.INV(RAND(),AVERAGE([1]Team_Inputs!$H$2:$H$15),STDEV([1]Team_Inputs!$H$2:$H$15)),2) -> 6.21 | V3: =ROUND(_xlfn.NORM.INV(RAND(),AVERAGE([1]Team_Inputs!$H$2:$H$15),STDEV([1]Team_Inputs!$H$2:$H$15)),2) -> 6.73 | W3: =ROUND(_xlfn.NORM.INV(RAND(),AVERAGE([1]Team_Inputs!$H$2:$H$15),STDEV([1]Team_Inputs!$H$2:$H$15)),2) -> 6.71 | X3: =ROUND(_xlfn.NORM.INV(RAND(),AVERAGE([1]Team_Inputs!$H$2:$H$15),STDEV([1]Team_Inputs!$H$2:$H$15)),2) -> 5.96 | Y3: =ROUND(_xlfn.NORM.INV(RAND(),AVERAGE([1]Team_Inputs!$H$2:$H$15),STDEV([1]Team_Inputs!$H$2:$H$15)),2) -> 6.8 | Z3: =ROUND(_xlfn.NORM.INV(RAND(),AVERAGE([1]Team_Inputs!$H$2:$H$15),STDEV([1]Team_Inputs!$H$2:$H$15)),2) -> 7.42 | ... AC3: =ROUND(_xlfn.NORM.INV(RAND(),AVERAGE([1]Team_Inputs!$H$2:$H$15),STDEV([1]Team_Inputs!$H$2:$H$15)),2) -> 7.53
A4: Fenerbahçe | B4: Beşiktaş | C4: Away | D4: 4-2-3-1 | E4: 4-2-3-1 | F4: =VLOOKUP(B4,Sheet2!A:E,5,0) -> 4 | H4: =ROUND(_xlfn.NORM.INV(RAND(),AVERAGE(Team_Inputs!#REF!),STDEV(Team_Inputs!#REF!)),2) -> #REF! | I4: =ROUND(_xlfn.NORM.INV(RAND(),AVERAGE(Team_Inputs!#REF!),STDEV(Team_Inputs!#REF!)),2) -> #REF! | J4: =ROUND(_xlfn.NORM.INV(RAND(),AVERAGE(Team_Inputs!#REF!),STDEV(Team_Inputs!#REF!)),2) -> #REF! | K4: =ROUND(_xlfn.NORM.INV(RAND(),AVERAGE(Team_Inputs!#REF!),STDEV(Team_Inputs!#REF!)),2) -> #REF! | L4: =ROUND(_xlfn.NORM.INV(RAND(),AVERAGE(Team_Inputs!#REF!),STDEV(Team_Inputs!#REF!)),2) -> #REF! | M4: =ROUND(_xlfn.NORM.INV(RAND(),AVERAGE(Team_Inputs!#REF!),STDEV(Team_Inputs!#REF!)),2) -> #REF! | N4: =ROUND(_xlfn.NORM.INV(RAND(),AVERAGE(Team_Inputs!#REF!),STDEV(Team_Inputs!#REF!)),2) -> #REF! | O4: =ROUND(_xlfn.NORM.INV(RAND(),AVERAGE(Team_Inputs!#REF!),STDEV(Team_Inputs!#REF!)),2) -> #REF! | ... R4: =ROUND(_xlfn.NORM.INV(RAND(),AVERAGE(Team_Inputs!#REF!),STDEV(Team_Inputs!#REF!)),2) -> #REF! | S4: =ROUND(_xlfn.NORM.INV(RAND(),AVERAGE([1]Team_Inputs!$H$2:$H$15),STDEV([1]Team_Inputs!$H$2:$H$15)),2) -> 7.04 | T4: =ROUND(_xlfn.NORM.INV(RAND(),AVERAGE([1]Team_Inputs!$H$2:$H$15),STDEV([1]Team_Inputs!$H$2:$H$15)),2) -> 7.27 | U4: =ROUND(_xlfn.NORM.INV(RAND(),AVERAGE([1]Team_Inputs!$H$2:$H$15),STDEV([1]Team_Inputs!$H$2:$H$15)),2) -> 7.19 | V4: =ROUND(_xlfn.NORM.INV(RAND(),AVERAGE([1]Team_Inputs!$H$2:$H$15),STDEV([1]Team_Inputs!$H$2:$H$15)),2) -> 6.92 | W4: =ROUND(_xlfn.NORM.INV(RAND(),AVERAGE([1]Team_Inputs!$H$2:$H$15),STDEV([1]Team_Inputs!$H$2:$H$15)),2) -> 5.85 | X4: =ROUND(_xlfn.NORM.INV(RAND(),AVERAGE([1]Team_Inputs!$H$2:$H$15),STDEV([1]Team_Inputs!$H$2:$H$15)),2) -> 6.88 | Y4: =ROUND(_xlfn.NORM.INV(RAND(),AVERAGE([1]Team_Inputs!$H$2:$H$15),STDEV([1]Team_Inputs!$H$2:$H$15)),2) -> 6.18 | Z4: =ROUND(_xlfn.NORM.INV(RAND(),AVERAGE([1]Team_Inputs!$H$2:$H$15),STDEV([1]Team_Inputs!$H$2:$H$15)),2) -> 5.77 | ... AC4: =ROUND(_xlfn.NORM.INV(RAND(),AVERAGE([1]Team_Inputs!$H$2:$H$15),STDEV([1]Team_Inputs!$H$2:$H$15)),2) -> 6.62
A5: Fenerbahçe | B5: Beşiktaş | C5: Away | D5: 4-2-3-1 | E5: 4-2-3-1 | F5: =VLOOKUP(B5,Sheet2!A:E,5,0) -> 4 | H5: =ROUND(_xlfn.NORM.INV(RAND(),AVERAGE(Team_Inputs!#REF!),STDEV(Team_Inputs!#REF!)),2) -> #REF! | I5: =ROUND(_xlfn.NORM.INV(RAND(),AVERAGE(Team_Inputs!#REF!),STDEV(Team_Inputs!#REF!)),2) -> #REF! | J5: =ROUND(_xlfn.NORM.INV(RAND(),AVERAGE(Team_Inputs!#REF!),STDEV(Team_Inputs!#REF!)),2) -> #REF! | K5: =ROUND(_xlfn.NORM.INV(RAND(),AVERAGE(Team_Inputs!#REF!),STDEV(Team_Inputs!#REF!)),2) -> #REF! | L5: =ROUND(_xlfn.NORM.INV(RAND(),AVERAGE(Team_Inputs!#REF!),STDEV(Team_Inputs!#REF!)),2) -> #REF! | M5: =ROUND(_xlfn.NORM.INV(RAND(),AVERAGE(Team_Inputs!#REF!),STDEV(Team_Inputs!#REF!)),2) -> #REF! | N5: =ROUND(_xlfn.NORM.INV(RAND(),AVERAGE(Team_Inputs!#REF!),STDEV(Team_Inputs!#REF!)),2) -> #REF! | O5: =ROUND(_xlfn.NORM.INV(RAND(),AVERAGE(Team_Inputs!#REF!),STDEV(Team_Inputs!#REF!)),2) -> #REF! | ... R5: =ROUND(_xlfn.NORM.INV(RAND(),AVERAGE(Team_Inputs!#REF!),STDEV(Team_Inputs!#REF!)),2) -> #REF! | S5: =ROUND(_xlfn.NORM.INV(RAND(),AVERAGE([1]Team_Inputs!$H$2:$H$15),STDEV([1]Team_Inputs!$H$2:$H$15)),2) -> 6.49 | T5: =ROUND(_xlfn.NORM.INV(RAND(),AVERAGE([1]Team_Inputs!$H$2:$H$15),STDEV([1]Team_Inputs!$H$2:$H$15)),2) -> 6.53 | U5: =ROUND(_xlfn.NORM.INV(RAND(),AVERAGE([1]Team_Inputs!$H$2:$H$15),STDEV([1]Team_Inputs!$H$2:$H$15)),2) -> 5.82 | V5: =ROUND(_xlfn.NORM.INV(RAND(),AVERAGE([1]Team_Inputs!$H$2:$H$15),STDEV([1]Team_Inputs!$H$2:$H$15)),2) -> 6.66 | W5: =ROUND(_xlfn.NORM.INV(RAND(),AVERAGE([1]Team_Inputs!$H$2:$H$15),STDEV([1]Team_Inputs!$H$2:$H$15)),2) -> 8.11 | X5: =ROUND(_xlfn.NORM.INV(RAND(),AVERAGE([1]Team_Inputs!$H$2:$H$15),STDEV([1]Team_Inputs!$H$2:$H$15)),2) -> 6.97 | Y5: =ROUND(_xlfn.NORM.INV(RAND(),AVERAGE([1]Team_Inputs!$H$2:$H$15),STDEV([1]Team_Inputs!$H$2:$H$15)),2) -> 6.25 | Z5: =ROUND(_xlfn.NORM.INV(RAND(),AVERAGE([1]Team_Inputs!$H$2:$H$15),STDEV([1]Team_Inputs!$H$2:$H$15)),2) -> 6.45 | ... AC5: =ROUND(_xlfn.NORM.INV(RAND(),AVERAGE([1]Team_Inputs!$H$2:$H$15),STDEV([1]Team_Inputs!$H$2:$H$15)),2) -> 7.09
A6: Fenerbahçe | B6: Beşiktaş | C6: Away | D6: 4-2-3-1 | E6: 4-2-3-1 | F6: =VLOOKUP(B6,Sheet2!A:E,5,0) -> 4 | H6: =ROUND(_xlfn.NORM.INV(RAND(),AVERAGE(Team_Inputs!#REF!),STDEV(Team_Inputs!#REF!)),2) -> #REF! | I6: =ROUND(_xlfn.NORM.INV(RAND(),AVERAGE(Team_Inputs!#REF!),STDEV(Team_Inputs!#REF!)),2) -> #REF! | J6: =ROUND(_xlfn.NORM.INV(RAND(),AVERAGE(Team_Inputs!#REF!),STDEV(Team_Inputs!#REF!)),2) -> #REF! | K6: =ROUND(_xlfn.NORM.INV(RAND(),AVERAGE(Team_Inputs!#REF!),STDEV(Team_Inputs!#REF!)),2) -> #REF! | L6: =ROUND(_xlfn.NORM.INV(RAND(),AVERAGE(Team_Inputs!#REF!),STDEV(Team_Inputs!#REF!)),2) -> #REF! | M6: =ROUND(_xlfn.NORM.INV(RAND(),AVERAGE(Team_Inputs!#REF!),STDEV(Team_Inputs!#REF!)),2) -> #REF! | N6: =ROUND(_xlfn.NORM.INV(RAND(),AVERAGE(Team_Inputs!#REF!),STDEV(Team_Inputs!#REF!)),2) -> #REF! | O6: =ROUND(_xlfn.NORM.INV(RAND(),AVERAGE(Team_Inputs!#REF!),STDEV(Team_Inputs!#REF!)),2) -> #REF! | ... R6: =ROUND(_xlfn.NORM.INV(RAND(),AVERAGE(Team_Inputs!#REF!),STDEV(Team_Inputs!#REF!)),2) -> #REF! | S6: =ROUND(_xlfn.NORM.INV(RAND(),AVERAGE([1]Team_Inputs!$H$2:$H$15),STDEV([1]Team_Inputs!$H$2:$H$15)),2) -> 7.72 | T6: =ROUND(_xlfn.NORM.INV(RAND(),AVERAGE([1]Team_Inputs!$H$2:$H$15),STDEV([1]Team_Inputs!$H$2:$H$15)),2) -> 6.52 | U6: =ROUND(_xlfn.NORM.INV(RAND(),AVERAGE([1]Team_Inputs!$H$2:$H$15),STDEV([1]Team_Inputs!$H$2:$H$15)),2) -> 7.36 | V6: =ROUND(_xlfn.NORM.INV(RAND(),AVERAGE([1]Team_Inputs!$H$2:$H$15),STDEV([1]Team_Inputs!$H$2:$H$15)),2) -> 6.81 | W6: =ROUND(_xlfn.NORM.INV(RAND(),AVERAGE([1]Team_Inputs!$H$2:$H$15),STDEV([1]Team_Inputs!$H$2:$H$15)),2) -> 6.88 | X6: =ROUND(_xlfn.NORM.INV(RAND(),AVERAGE([1]Team_Inputs!$H$2:$H$15),STDEV([1]Team_Inputs!$H$2:$H$15)),2) -> 7.38 | Y6: =ROUND(_xlfn.NORM.INV(RAND(),AVERAGE([1]Team_Inputs!$H$2:$H$15),STDEV([1]Team_Inputs!$H$2:$H$15)),2) -> 5.8 | Z6: =ROUND(_xlfn.NORM.INV(RAND(),AVERAGE([1]Team_Inputs!$H$2:$H$15),STDEV([1]Team_Inputs!$H$2:$H$15)),2) -> 8.25 | ... AC6: =ROUND(_xlfn.NORM.INV(RAND(),AVERAGE([1]Team_Inputs!$H$2:$H$15),STDEV([1]Team_Inputs!$H$2:$H$15)),2) -> 6.25
A7: Fenerbahçe | B7: Beşiktaş | C7: Away | D7: 4-2-3-1 | E7: 4-2-3-1 | F7: =VLOOKUP(B7,Sheet2!A:E,5,0) -> 4 | H7: =ROUND(_xlfn.NORM.INV(RAND(),AVERAGE(Team_Inputs!#REF!),STDEV(Team_Inputs!#REF!)),2) -> #REF! | I7: =ROUND(_xlfn.NORM.INV(RAND(),AVERAGE(Team_Inputs!#REF!),STDEV(Team_Inputs!#REF!)),2) -> #REF! | J7: =ROUND(_xlfn.NORM.INV(RAND(),AVERAGE(Team_Inputs!#REF!),STDEV(Team_Inputs!#REF!)),2) -> #REF! | K7: =ROUND(_xlfn.NORM.INV(RAND(),AVERAGE(Team_Inputs!#REF!),STDEV(Team_Inputs!#REF!)),2) -> #REF! | L7: =ROUND(_xlfn.NORM.INV(RAND(),AVERAGE(Team_Inputs!#REF!),STDEV(Team_Inputs!#REF!)),2) -> #REF! | M7: =ROUND(_xlfn.NORM.INV(RAND(),AVERAGE(Team_Inputs!#REF!),STDEV(Team_Inputs!#REF!)),2) -> #REF! | N7: =ROUND(_xlfn.NORM.INV(RAND(),AVERAGE(Team_Inputs!#REF!),STDEV(Team_Inputs!#REF!)),2) -> #REF! | O7: =ROUND(_xlfn.NORM.INV(RAND(),AVERAGE(Team_Inputs!#REF!),STDEV(Team_Inputs!#REF!)),2) -> #REF! | ... R7: =ROUND(_xlfn.NORM.INV(RAND(),AVERAGE(Team_Inputs!#REF!),STDEV(Team_Inputs!#REF!)),2) -> #REF! | S7: =ROUND(_xlfn.NORM.INV(RAND(),AVERAGE([1]Team_Inputs!$H$2:$H$15),STDEV([1]Team_Inputs!$H$2:$H$15)),2) -> 6.39 | T7: =ROUND(_xlfn.NORM.INV(RAND(),AVERAGE([1]Team_Inputs!$H$2:$H$15),STDEV([1]Team_Inputs!$H$2:$H$15)),2) -> 6.44 | U7: =ROUND(_xlfn.NORM.INV(RAND(),AVERAGE([1]Team_Inputs!$H$2:$H$15),STDEV([1]Team_Inputs!$H$2:$H$15)),2) -> 6.25 | V7: =ROUND(_xlfn.NORM.INV(RAND(),AVERAGE([1]Team_Inputs!$H$2:$H$15),STDEV([1]Team_Inputs!$H$2:$H$15)),2) -> 7.51 | W7: =ROUND(_xlfn.NORM.INV(RAND(),AVERAGE([1]Team_Inputs!$H$2:$H$15),STDEV([1]Team_Inputs!$H$2:$H$15)),2) -> 6.34 | X7: =ROUND(_xlfn.NORM.INV(RAND(),AVERAGE([1]Team_Inputs!$H$2:$H$15),STDEV([1]Team_Inputs!$H$2:$H$15)),2) -> 6.55 | Y7: =ROUND(_xlfn.NORM.INV(RAND(),AVERAGE([1]Team_Inputs!$H$2:$H$15),STDEV([1]Team_Inputs!$H$2:$H$15)),2) -> 6.46 | Z7: =ROUND(_xlfn.NORM.INV(RAND(),AVERAGE([1]Team_Inputs!$H$2:$H$15),STDEV([1]Team_Inputs!$H$2:$H$15)),2) -> 7.61 | ... AC7: =ROUND(_xlfn.NORM.INV(RAND(),AVERAGE([1]Team_Inputs!$H$2:$H$15),STDEV([1]Team_Inputs!$H$2:$H$15)),2) -> 5.74
A8: Fenerbahçe | B8: Beşiktaş | C8: Away | D8: 4-2-3-1 | E8: 4-2-3-1 | F8: =VLOOKUP(B8,Sheet2!A:E,5,0) -> 4 | H8: =ROUND(_xlfn.NORM.INV(RAND(),AVERAGE(Team_Inputs!#REF!),STDEV(Team_Inputs!#REF!)),2) -> #REF! | I8: =ROUND(_xlfn.NORM.INV(RAND(),AVERAGE(Team_Inputs!#REF!),STDEV(Team_Inputs!#REF!)),2) -> #REF! | J8: =ROUND(_xlfn.NORM.INV(RAND(),AVERAGE(Team_Inputs!#REF!),STDEV(Team_Inputs!#REF!)),2) -> #REF! | K8: =ROUND(_xlfn.NORM.INV(RAND(),AVERAGE(Team_Inputs!#REF!),STDEV(Team_Inputs!#REF!)),2) -> #REF! | L8: =ROUND(_xlfn.NORM.INV(RAND(),AVERAGE(Team_Inputs!#REF!),STDEV(Team_Inputs!#REF!)),2) -> #REF! | M8: =ROUND(_xlfn.NORM.INV(RAND(),AVERAGE(Team_Inputs!#REF!),STDEV(Team_Inputs!#REF!)),2) -> #REF! | N8: =ROUND(_xlfn.NORM.INV(RAND(),AVERAGE(Team_Inputs!#REF!),STDEV(Team_Inputs!#REF!)),2) -> #REF! | O8: =ROUND(_xlfn.NORM.INV(RAND(),AVERAGE(Team_Inputs!#REF!),STDEV(Team_Inputs!#REF!)),2) -> #REF! | ... R8: =ROUND(_xlfn.NORM.INV(RAND(),AVERAGE(Team_Inputs!#REF!),STDEV(Team_Inputs!#REF!)),2) -> #REF! | S8: =ROUND(_xlfn.NORM.INV(RAND(),AVERAGE([1]Team_Inputs!$H$2:$H$15),STDEV([1]Team_Inputs!$H$2:$H$15)),2) -> 6.25 | T8: =ROUND(_xlfn.NORM.INV(RAND(),AVERAGE([1]Team_Inputs!$H$2:$H$15),STDEV([1]Team_Inputs!$H$2:$H$15)),2) -> 7.77 | U8: =ROUND(_xlfn.NORM.INV(RAND(),AVERAGE([1]Team_Inputs!$H$2:$H$15),STDEV([1]Team_Inputs!$H$2:$H$15)),2) -> 7.56 | V8: =ROUND(_xlfn.NORM.INV(RAND(),AVERAGE([1]Team_Inputs!$H$2:$H$15),STDEV([1]Team_Inputs!$H$2:$H$15)),2) -> 6.42 | W8: =ROUND(_xlfn.NORM.INV(RAND(),AVERAGE([1]Team_Inputs!$H$2:$H$15),STDEV([1]Team_Inputs!$H$2:$H$15)),2) -> 6.28 | X8: =ROUND(_xlfn.NORM.INV(RAND(),AVERAGE([1]Team_Inputs!$H$2:$H$15),STDEV([1]Team_Inputs!$H$2:$H$15)),2) -> 7.38 | Y8: =ROUND(_xlfn.NORM.INV(RAND(),AVERAGE([1]Team_Inputs!$H$2:$H$15),STDEV([1]Team_Inputs!$H$2:$H$15)),2) -> 7.29 | Z8: =ROUND(_xlfn.NORM.INV(RAND(),AVERAGE([1]Team_Inputs!$H$2:$H$15),STDEV([1]Team_Inputs!$H$2:$H$15)),2) -> 5.57 | ... AC8: =ROUND(_xlfn.NORM.INV(RAND(),AVERAGE([1]Team_Inputs!$H$2:$H$15),STDEV([1]Team_Inputs!$H$2:$H$15)),2) -> 6.66
A9: Fenerbahçe | B9: Beşiktaş | C9: Away | D9: 4-2-3-1 | E9: 4-2-3-1 | F9: =VLOOKUP(B9,Sheet2!A:E,5,0) -> 4 | H9: =ROUND(_xlfn.NORM.INV(RAND(),AVERAGE(Team_Inputs!#REF!),STDEV(Team_Inputs!#REF!)),2) -> #REF! | I9: =ROUND(_xlfn.NORM.INV(RAND(),AVERAGE(Team_Inputs!#REF!),STDEV(Team_Inputs!#REF!)),2) -> #REF! | J9: =ROUND(_xlfn.NORM.INV(RAND(),AVERAGE(Team_Inputs!#REF!),STDEV(Team_Inputs!#REF!)),2) -> #REF! | K9: =ROUND(_xlfn.NORM.INV(RAND(),AVERAGE(Team_Inputs!#REF!),STDEV(Team_Inputs!#REF!)),2) -> #REF! | L9: =ROUND(_xlfn.NORM.INV(RAND(),AVERAGE(Team_Inputs!#REF!),STDEV(Team_Inputs!#REF!)),2) -> #REF! | M9: =ROUND(_xlfn.NORM.INV(RAND(),AVERAGE(Team_Inputs!#REF!),STDEV(Team_Inputs!#REF!)),2) -> #REF! | N9: =ROUND(_xlfn.NORM.INV(RAND(),AVERAGE(Team_Inputs!#REF!),STDEV(Team_Inputs!#REF!)),2) -> #REF! | O9: =ROUND(_xlfn.NORM.INV(RAND(),AVERAGE(Team_Inputs!#REF!),STDEV(Team_Inputs!#REF!)),2) -> #REF! | ... R9: =ROUND(_xlfn.NORM.INV(RAND(),AVERAGE(Team_Inputs!#REF!),STDEV(Team_Inputs!#REF!)),2) -> #REF! | S9: =ROUND(_xlfn.NORM.INV(RAND(),AVERAGE([1]Team_Inputs!$H$2:$H$15),STDEV([1]Team_Inputs!$H$2:$H$15)),2) -> 7.13 | T9: =ROUND(_xlfn.NORM.INV(RAND(),AVERAGE([1]Team_Inputs!$H$2:$H$15),STDEV([1]Team_Inputs!$H$2:$H$15)),2) -> 7.4 | U9: =ROUND(_xlfn.NORM.INV(RAND(),AVERAGE([1]Team_Inputs!$H$2:$H$15),STDEV([1]Team_Inputs!$H$2:$H$15)),2) -> 8.72 | V9: =ROUND(_xlfn.NORM.INV(RAND(),AVERAGE([1]Team_Inputs!$H$2:$H$15),STDEV([1]Team_Inputs!$H$2:$H$15)),2) -> 7.36 | W9: =ROUND(_xlfn.NORM.INV(RAND(),AVERAGE([1]Team_Inputs!$H$2:$H$15),STDEV([1]Team_Inputs!$H$2:$H$15)),2) -> 7.48 | X9: =ROUND(_xlfn.NORM.INV(RAND(),AVERAGE([1]Team_Inputs!$H$2:$H$15),STDEV([1]Team_Inputs!$H$2:$H$15)),2) -> 6.9 | Y9: =ROUND(_xlfn.NORM.INV(RAND(),AVERAGE([1]Team_Inputs!$H$2:$H$15),STDEV([1]Team_Inputs!$H$2:$H$15)),2) -> 6.67 | Z9: =ROUND(_xlfn.NORM.INV(RAND(),AVERAGE([1]Team_Inputs!$H$2:$H$15),STDEV([1]Team_Inputs!$H$2:$H$15)),2) -> 6.39 | ... AC9: =ROUND(_xlfn.NORM.INV(RAND(),AVERAGE([1]Team_Inputs!$H$2:$H$15),STDEV([1]Team_Inputs!$H$2:$H$15)),2) -> 6.78
A10: Fenerbahçe | B10: Beşiktaş | C10: Away | D10: 4-2-3-1 | E10: 4-2-3-1 | F10: =VLOOKUP(B10,Sheet2!A:E,5,0) -> 4 | H10: =ROUND(_xlfn.NORM.INV(RAND(),AVERAGE(Team_Inputs!#REF!),STDEV(Team_Inputs!#REF!)),2) -> #REF! | I10: =ROUND(_xlfn.NORM.INV(RAND(),AVERAGE(Team_Inputs!#REF!),STDEV(Team_Inputs!#REF!)),2) -> #REF! | J10: =ROUND(_xlfn.NORM.INV(RAND(),AVERAGE(Team_Inputs!#REF!),STDEV(Team_Inputs!#REF!)),2) -> #REF! | K10: =ROUND(_xlfn.NORM.INV(RAND(),AVERAGE(Team_Inputs!#REF!),STDEV(Team_Inputs!#REF!)),2) -> #REF! | L10: =ROUND(_xlfn.NORM.INV(RAND(),AVERAGE(Team_Inputs!#REF!),STDEV(Team_Inputs!#REF!)),2) -> #REF! | M10: =ROUND(_xlfn.NORM.INV(RAND(),AVERAGE(Team_Inputs!#REF!),STDEV(Team_Inputs!#REF!)),2) -> #REF! | N10: =ROUND(_xlfn.NORM.INV(RAND(),AVERAGE(Team_Inputs!#REF!),STDEV(Team_Inputs!#REF!)),2) -> #REF! | O10: =ROUND(_xlfn.NORM.INV(RAND(),AVERAGE(Team_Inputs!#REF!),STDEV(Team_Inputs!#REF!)),2) -> #REF! | ... R10: =ROUND(_xlfn.NORM.INV(RAND(),AVERAGE(Team_Inputs!#REF!),STDEV(Team_Inputs!#REF!)),2) -> #REF! | S10: =ROUND(_xlfn.NORM.INV(RAND(),AVERAGE([1]Team_Inputs!$H$2:$H$15),STDEV([1]Team_Inputs!$H$2:$H$15)),2) -> 8.18 | T10: =ROUND(_xlfn.NORM.INV(RAND(),AVERAGE([1]Team_Inputs!$H$2:$H$15),STDEV([1]Team_Inputs!$H$2:$H$15)),2) -> 7.22 | U10: =ROUND(_xlfn.NORM.INV(RAND(),AVERAGE([1]Team_Inputs!$H$2:$H$15),STDEV([1]Team_Inputs!$H$2:$H$15)),2) -> 5.62 | V10: =ROUND(_xlfn.NORM.INV(RAND(),AVERAGE([1]Team_Inputs!$H$2:$H$15),STDEV([1]Team_Inputs!$H$2:$H$15)),2) -> 7.23 | W10: =ROUND(_xlfn.NORM.INV(RAND(),AVERAGE([1]Team_Inputs!$H$2:$H$15),STDEV([1]Team_Inputs!$H$2:$H$15)),2) -> 7.49 | X10: =ROUND(_xlfn.NORM.INV(RAND(),AVERAGE([1]Team_Inputs!$H$2:$H$15),STDEV([1]Team_Inputs!$H$2:$H$15)),2) -> 7.12 | Y10: =ROUND(_xlfn.NORM.INV(RAND(),AVERAGE([1]Team_Inputs!$H$2:$H$15),STDEV([1]Team_Inputs!$H$2:$H$15)),2) -> 6.91 | Z10: =ROUND(_xlfn.NORM.INV(RAND(),AVERAGE([1]Team_Inputs!$H$2:$H$15),STDEV([1]Team_Inputs!$H$2:$H$15)),2) -> 5.54 | ... AC10: =ROUND(_xlfn.NORM.INV(RAND(),AVERAGE([1]Team_Inputs!$H$2:$H$15),STDEV([1]Team_Inputs!$H$2:$H$15)),2) -> 6.88
A11: Fenerbahçe | B11: Beşiktaş | C11: Away | D11: 4-2-3-1 | E11: 4-2-3-1 | F11: =VLOOKUP(B11,Sheet2!A:E,5,0) -> 4 | H11: =ROUND(_xlfn.NORM.INV(RAND(),AVERAGE(Team_Inputs!#REF!),STDEV(Team_Inputs!#REF!)),2) -> #REF! | I11: =ROUND(_xlfn.NORM.INV(RAND(),AVERAGE(Team_Inputs!#REF!),STDEV(Team_Inputs!#REF!)),2) -> #REF! | J11: =ROUND(_xlfn.NORM.INV(RAND(),AVERAGE(Team_Inputs!#REF!),STDEV(Team_Inputs!#REF!)),2) -> #REF! | K11: =ROUND(_xlfn.NORM.INV(RAND(),AVERAGE(Team_Inputs!#REF!),STDEV(Team_Inputs!#REF!)),2) -> #REF! | L11: =ROUND(_xlfn.NORM.INV(RAND(),AVERAGE(Team_Inputs!#REF!),STDEV(Team_Inputs!#REF!)),2) -> #REF! | M11: =ROUND(_xlfn.NORM.INV(RAND(),AVERAGE(Team_Inputs!#REF!),STDEV(Team_Inputs!#REF!)),2) -> #REF! | N11: =ROUND(_xlfn.NORM.INV(RAND(),AVERAGE(Team_Inputs!#REF!),STDEV(Team_Inputs!#REF!)),2) -> #REF! | O11: =ROUND(_xlfn.NORM.INV(RAND(),AVERAGE(Team_Inputs!#REF!),STDEV(Team_Inputs!#REF!)),2) -> #REF! | ... R11: =ROUND(_xlfn.NORM.INV(RAND(),AVERAGE(Team_Inputs!#REF!),STDEV(Team_Inputs!#REF!)),2) -> #REF! | S11: =ROUND(_xlfn.NORM.INV(RAND(),AVERAGE([1]Team_Inputs!$H$2:$H$15),STDEV([1]Team_Inputs!$H$2:$H$15)),2) -> 7.11 | T11: =ROUND(_xlfn.NORM.INV(RAND(),AVERAGE([1]Team_Inputs!$H$2:$H$15),STDEV([1]Team_Inputs!$H$2:$H$15)),2) -> 5.86 | U11: =ROUND(_xlfn.NORM.INV(RAND(),AVERAGE([1]Team_Inputs!$H$2:$H$15),STDEV([1]Team_Inputs!$H$2:$H$15)),2) -> 6.87 | V11: =ROUND(_xlfn.NORM.INV(RAND(),AVERAGE([1]Team_Inputs!$H$2:$H$15),STDEV([1]Team_Inputs!$H$2:$H$15)),2) -> 6.47 | W11: =ROUND(_xlfn.NORM.INV(RAND(),AVERAGE([1]Team_Inputs!$H$2:$H$15),STDEV([1]Team_Inputs!$H$2:$H$15)),2) -> 6.98 | X11: =ROUND(_xlfn.NORM.INV(RAND(),AVERAGE([1]Team_Inputs!$H$2:$H$15),STDEV([1]Team_Inputs!$H$2:$H$15)),2) -> 7.77 | Y11: =ROUND(_xlfn.NORM.INV(RAND(),AVERAGE([1]Team_Inputs!$H$2:$H$15),STDEV([1]Team_Inputs!$H$2:$H$15)),2) -> 6.22 | Z11: =ROUND(_xlfn.NORM.INV(RAND(),AVERAGE([1]Team_Inputs!$H$2:$H$15),STDEV([1]Team_Inputs!$H$2:$H$15)),2) -> 6.1 | ... AC11: =ROUND(_xlfn.NORM.INV(RAND(),AVERAGE([1]Team_Inputs!$H$2:$H$15),STDEV([1]Team_Inputs!$H$2:$H$15)),2) -> 6.2
A12: Fenerbahçe | B12: Beşiktaş | C12: Away | D12: 4-2-3-1 | E12: 4-2-3-1 | F12: =VLOOKUP(B12,Sheet2!A:E,5,0) -> 4 | H12: =ROUND(_xlfn.NORM.INV(RAND(),AVERAGE(Team_Inputs!#REF!),STDEV(Team_Inputs!#REF!)),2) -> #REF! | I12: =ROUND(_xlfn.NORM.INV(RAND(),AVERAGE(Team_Inputs!#REF!),STDEV(Team_Inputs!#REF!)),2) -> #REF! | J12: =ROUND(_xlfn.NORM.INV(RAND(),AVERAGE(Team_Inputs!#REF!),STDEV(Team_Inputs!#REF!)),2) -> #REF! | K12: =ROUND(_xlfn.NORM.INV(RAND(),AVERAGE(Team_Inputs!#REF!),STDEV(Team_Inputs!#REF!)),2) -> #REF! | L12: =ROUND(_xlfn.NORM.INV(RAND(),AVERAGE(Team_Inputs!#REF!),STDEV(Team_Inputs!#REF!)),2) -> #REF! | M12: =ROUND(_xlfn.NORM.INV(RAND(),AVERAGE(Team_Inputs!#REF!),STDEV(Team_Inputs!#REF!)),2) -> #REF! | N12: =ROUND(_xlfn.NORM.INV(RAND(),AVERAGE(Team_Inputs!#REF!),STDEV(Team_Inputs!#REF!)),2) -> #REF! | O12: =ROUND(_xlfn.NORM.INV(RAND(),AVERAGE(Team_Inputs!#REF!),STDEV(Team_Inputs!#REF!)),2) -> #REF! | ... R12: =ROUND(_xlfn.NORM.INV(RAND(),AVERAGE(Team_Inputs!#REF!),STDEV(Team_Inputs!#REF!)),2) -> #REF! | S12: =ROUND(_xlfn.NORM.INV(RAND(),AVERAGE([1]Team_Inputs!$H$2:$H$15),STDEV([1]Team_Inputs!$H$2:$H$15)),2) -> 6.11 | T12: =ROUND(_xlfn.NORM.INV(RAND(),AVERAGE([1]Team_Inputs!$H$2:$H$15),STDEV([1]Team_Inputs!$H$2:$H$15)),2) -> 7.37 | U12: =ROUND(_xlfn.NORM.INV(RAND(),AVERAGE([1]Team_Inputs!$H$2:$H$15),STDEV([1]Team_Inputs!$H$2:$H$15)),2) -> 6.79 | V12: =ROUND(_xlfn.NORM.INV(RAND(),AVERAGE([1]Team_Inputs!$H$2:$H$15),STDEV([1]Team_Inputs!$H$2:$H$15)),2) -> 6.03 | W12: =ROUND(_xlfn.NORM.INV(RAND(),AVERAGE([1]Team_Inputs!$H$2:$H$15),STDEV([1]Team_Inputs!$H$2:$H$15)),2) -> 6.94 | X12: =ROUND(_xlfn.NORM.INV(RAND(),AVERAGE([1]Team_Inputs!$H$2:$H$15),STDEV([1]Team_Inputs!$H$2:$H$15)),2) -> 6.47 | Y12: =ROUND(_xlfn.NORM.INV(RAND(),AVERAGE([1]Team_Inputs!$H$2:$H$15),STDEV([1]Team_Inputs!$H$2:$H$15)),2) -> 6.29 | Z12: =ROUND(_xlfn.NORM.INV(RAND(),AVERAGE([1]Team_Inputs!$H$2:$H$15),STDEV([1]Team_Inputs!$H$2:$H$15)),2) -> 7.23 | ... AC12: =ROUND(_xlfn.NORM.INV(RAND(),AVERAGE([1]Team_Inputs!$H$2:$H$15),STDEV([1]Team_Inputs!$H$2:$H$15)),2) -> 6.64
A13: Fenerbahçe | B13: Beşiktaş | C13: Away | D13: 4-2-3-1 | E13: 4-2-3-1 | F13: =VLOOKUP(B13,Sheet2!A:E,5,0) -> 4 | H13: =ROUND(_xlfn.NORM.INV(RAND(),AVERAGE(Team_Inputs!#REF!),STDEV(Team_Inputs!#REF!)),2) -> #REF! | I13: =ROUND(_xlfn.NORM.INV(RAND(),AVERAGE(Team_Inputs!#REF!),STDEV(Team_Inputs!#REF!)),2) -> #REF! | J13: =ROUND(_xlfn.NORM.INV(RAND(),AVERAGE(Team_Inputs!#REF!),STDEV(Team_Inputs!#REF!)),2) -> #REF! | K13: =ROUND(_xlfn.NORM.INV(RAND(),AVERAGE(Team_Inputs!#REF!),STDEV(Team_Inputs!#REF!)),2) -> #REF! | L13: =ROUND(_xlfn.NORM.INV(RAND(),AVERAGE(Team_Inputs!#REF!),STDEV(Team_Inputs!#REF!)),2) -> #REF! | M13: =ROUND(_xlfn.NORM.INV(RAND(),AVERAGE(Team_Inputs!#REF!),STDEV(Team_Inputs!#REF!)),2) -> #REF! | N13: =ROUND(_xlfn.NORM.INV(RAND(),AVERAGE(Team_Inputs!#REF!),STDEV(Team_Inputs!#REF!)),2) -> #REF! | O13: =ROUND(_xlfn.NORM.INV(RAND(),AVERAGE(Team_Inputs!#REF!),STDEV(Team_Inputs!#REF!)),2) -> #REF! | ... R13: =ROUND(_xlfn.NORM.INV(RAND(),AVERAGE(Team_Inputs!#REF!),STDEV(Team_Inputs!#REF!)),2) -> #REF! | S13: =ROUND(_xlfn.NORM.INV(RAND(),AVERAGE([1]Team_Inputs!$H$2:$H$15),STDEV([1]Team_Inputs!$H$2:$H$15)),2) -> 7.77 | T13: =ROUND(_xlfn.NORM.INV(RAND(),AVERAGE([1]Team_Inputs!$H$2:$H$15),STDEV([1]Team_Inputs!$H$2:$H$15)),2) -> 7.41 | U13: =ROUND(_xlfn.NORM.INV(RAND(),AVERAGE([1]Team_Inputs!$H$2:$H$15),STDEV([1]Team_Inputs!$H$2:$H$15)),2) -> 7.13 | V13: =ROUND(_xlfn.NORM.INV(RAND(),AVERAGE([1]Team_Inputs!$H$2:$H$15),STDEV([1]Team_Inputs!$H$2:$H$15)),2) -> 6.62 | W13: =ROUND(_xlfn.NORM.INV(RAND(),AVERAGE([1]Team_Inputs!$H$2:$H$15),STDEV([1]Team_Inputs!$H$2:$H$15)),2) -> 6.59 | X13: =ROUND(_xlfn.NORM.INV(RAND(),AVERAGE([1]Team_Inputs!$H$2:$H$15),STDEV([1]Team_Inputs!$H$2:$H$15)),2) -> 5.53 | Y13: =ROUND(_xlfn.NORM.INV(RAND(),AVERAGE([1]Team_Inputs!$H$2:$H$15),STDEV([1]Team_Inputs!$H$2:$H$15)),2) -> 6.61 | Z13: =ROUND(_xlfn.NORM.INV(RAND(),AVERAGE([1]Team_Inputs!$H$2:$H$15),STDEV([1]Team_Inputs!$H$2:$H$15)),2) -> 8.36 | ... AC13: =ROUND(_xlfn.NORM.INV(RAND(),AVERAGE([1]Team_Inputs!$H$2:$H$15),STDEV([1]Team_Inputs!$H$2:$H$15)),2) -> 7.19
... A701: Fenerbahçe | B701: Beşiktaş | C701: Away | D701: 3-5-2 | E701: 3-5-2 | F701: =VLOOKUP(B701,Sheet2!A:E,5,0) -> 4 | H701: =ROUND(_xlfn.NORM.INV(RAND(),AVERAGE(Team_Inputs!#REF!),STDEV(Team_Inputs!#REF!)),2) -> #REF! | I701: =ROUND(_xlfn.NORM.INV(RAND(),AVERAGE(Team_Inputs!#REF!),STDEV(Team_Inputs!#REF!)),2) -> #REF! | J701: =ROUND(_xlfn.NORM.INV(RAND(),AVERAGE(Team_Inputs!#REF!),STDEV(Team_Inputs!#REF!)),2) -> #REF! | K701: =ROUND(_xlfn.NORM.INV(RAND(),AVERAGE(Team_Inputs!#REF!),STDEV(Team_Inputs!#REF!)),2) -> #REF! | L701: =ROUND(_xlfn.NORM.INV(RAND(),AVERAGE(Team_Inputs!#REF!),STDEV(Team_Inputs!#REF!)),2) -> #REF! | M701: =ROUND(_xlfn.NORM.INV(RAND(),AVERAGE(Team_Inputs!#REF!),STDEV(Team_Inputs!#REF!)),2) -> #REF! | N701: =ROUND(_xlfn.NORM.INV(RAND(),AVERAGE(Team_Inputs!#REF!),STDEV(Team_Inputs!#REF!)),2) -> #REF! | O701: =ROUND(_xlfn.NORM.INV(RAND(),AVERAGE(Team_Inputs!#REF!),STDEV(Team_Inputs!#REF!)),2) -> #REF! | ... R701: =ROUND(_xlfn.NORM.INV(RAND(),AVERAGE(Team_Inputs!#REF!),STDEV(Team_Inputs!#REF!)),2) -> #REF! | S701: =ROUND(_xlfn.NORM.INV(RAND(),AVERAGE([1]Team_Inputs!$H$2:$H$15),STDEV([1]Team_Inputs!$H$2:$H$15)),2) -> 6.63 | T701: =ROUND(_xlfn.NORM.INV(RAND(),AVERAGE([1]Team_Inputs!$H$2:$H$15),STDEV([1]Team_Inputs!$H$2:$H$15)),2) -> 6.05 | U701: =ROUND(_xlfn.NORM.INV(RAND(),AVERAGE([1]Team_Inputs!$H$2:$H$15),STDEV([1]Team_Inputs!$H$2:$H$15)),2) -> 5.54 | V701: =ROUND(_xlfn.NORM.INV(RAND(),AVERAGE([1]Team_Inputs!$H$2:$H$15),STDEV([1]Team_Inputs!$H$2:$H$15)),2) -> 6.01 | W701: =ROUND(_xlfn.NORM.INV(RAND(),AVERAGE([1]Team_Inputs!$H$2:$H$15),STDEV([1]Team_Inputs!$H$2:$H$15)),2) -> 7.14 | X701: =ROUND(_xlfn.NORM.INV(RAND(),AVERAGE([1]Team_Inputs!$H$2:$H$15),STDEV([1]Team_Inputs!$H$2:$H$15)),2) -> 6.46 | Y701: =ROUND(_xlfn.NORM.INV(RAND(),AVERAGE([1]Team_Inputs!$H$2:$H$15),STDEV([1]Team_Inputs!$H$2:$H$15)),2) -> 7.07 | Z701: =ROUND(_xlfn.NORM.INV(RAND(),AVERAGE([1]Team_Inputs!$H$2:$H$15),STDEV([1]Team_Inputs!$H$2:$H$15)),2) -> 6.5 | ... AC701: =ROUND(_xlfn.NORM.INV(RAND(),AVERAGE([1]Team_Inputs!$H$2:$H$15),STDEV([1]Team_Inputs!$H$2:$H$15)),2) -> 8.73
A702: Fenerbahçe | B702: Beşiktaş | C702: Away | D702: 3-5-2 | E702: 3-1-4-2 | H702: =ROUND(_xlfn.NORM.INV(RAND(),AVERAGE(Team_Inputs!#REF!),STDEV(Team_Inputs!#REF!)),2) -> #REF! | I702: =ROUND(_xlfn.NORM.INV(RAND(),AVERAGE(Team_Inputs!#REF!),STDEV(Team_Inputs!#REF!)),2) -> #REF! | J702: =ROUND(_xlfn.NORM.INV(RAND(),AVERAGE(Team_Inputs!#REF!),STDEV(Team_Inputs!#REF!)),2) -> #REF! | K702: =ROUND(_xlfn.NORM.INV(RAND(),AVERAGE(Team_Inputs!#REF!),STDEV(Team_Inputs!#REF!)),2) -> #REF! | L702: =ROUND(_xlfn.NORM.INV(RAND(),AVERAGE(Team_Inputs!#REF!),STDEV(Team_Inputs!#REF!)),2) -> #REF! | M702: =ROUND(_xlfn.NORM.INV(RAND(),AVERAGE(Team_Inputs!#REF!),STDEV(Team_Inputs!#REF!)),2) -> #REF! | N702: =ROUND(_xlfn.NORM.INV(RAND(),AVERAGE(Team_Inputs!#REF!),STDEV(Team_Inputs!#REF!)),2) -> #REF! | O702: =ROUND(_xlfn.NORM.INV(RAND(),AVERAGE(Team_Inputs!#REF!),STDEV(Team_Inputs!#REF!)),2) -> #REF! | ... R702: =ROUND(_xlfn.NORM.INV(RAND(),AVERAGE(Team_Inputs!#REF!),STDEV(Team_Inputs!#REF!)),2) -> #REF! | S702: =ROUND(_xlfn.NORM.INV(RAND(),AVERAGE([1]Team_Inputs!$H$2:$H$15),STDEV([1]Team_Inputs!$H$2:$H$15)),2) -> 6.5 | T702: =ROUND(_xlfn.NORM.INV(RAND(),AVERAGE([1]Team_Inputs!$H$2:$H$15),STDEV([1]Team_Inputs!$H$2:$H$15)),2) -> 6.74 | U702: =ROUND(_xlfn.NORM.INV(RAND(),AVERAGE([1]Team_Inputs!$H$2:$H$15),STDEV([1]Team_Inputs!$H$2:$H$15)),2) -> 7.63 | V702: =ROUND(_xlfn.NORM.INV(RAND(),AVERAGE([1]Team_Inputs!$H$2:$H$15),STDEV([1]Team_Inputs!$H$2:$H$15)),2) -> 6.2 | W702: =ROUND(_xlfn.NORM.INV(RAND(),AVERAGE([1]Team_Inputs!$H$2:$H$15),STDEV([1]Team_Inputs!$H$2:$H$15)),2) -> 7.84 | X702: =ROUND(_xlfn.NORM.INV(RAND(),AVERAGE([1]Team_Inputs!$H$2:$H$15),STDEV([1]Team_Inputs!$H$2:$H$15)),2) -> 7.52 | Y702: =ROUND(_xlfn.NORM.INV(RAND(),AVERAGE([1]Team_Inputs!$H$2:$H$15),STDEV([1]Team_Inputs!$H$2:$H$15)),2) -> 6.1 | Z702: =ROUND(_xlfn.NORM.INV(RAND(),AVERAGE([1]Team_Inputs!$H$2:$H$15),STDEV([1]Team_Inputs!$H$2:$H$15)),2) -> 6.3 | ... AC702: =ROUND(_xlfn.NORM.INV(RAND(),AVERAGE([1]Team_Inputs!$H$2:$H$15),STDEV([1]Team_Inputs!$H$2:$H$15)),2) -> 6.7
A703: Fenerbahçe | B703: Beşiktaş | C703: Away | D703: 3-5-2 | E703: 3-1-4-2 | H703: =ROUND(_xlfn.NORM.INV(RAND(),AVERAGE(Team_Inputs!#REF!),STDEV(Team_Inputs!#REF!)),2) -> #REF! | I703: =ROUND(_xlfn.NORM.INV(RAND(),AVERAGE(Team_Inputs!#REF!),STDEV(Team_Inputs!#REF!)),2) -> #REF! | J703: =ROUND(_xlfn.NORM.INV(RAND(),AVERAGE(Team_Inputs!#REF!),STDEV(Team_Inputs!#REF!)),2) -> #REF! | K703: =ROUND(_xlfn.NORM.INV(RAND(),AVERAGE(Team_Inputs!#REF!),STDEV(Team_Inputs!#REF!)),2) -> #REF! | L703: =ROUND(_xlfn.NORM.INV(RAND(),AVERAGE(Team_Inputs!#REF!),STDEV(Team_Inputs!#REF!)),2) -> #REF! | M703: =ROUND(_xlfn.NORM.INV(RAND(),AVERAGE(Team_Inputs!#REF!),STDEV(Team_Inputs!#REF!)),2) -> #REF! | N703: =ROUND(_xlfn.NORM.INV(RAND(),AVERAGE(Team_Inputs!#REF!),STDEV(Team_Inputs!#REF!)),2) -> #REF! | O703: =ROUND(_xlfn.NORM.INV(RAND(),AVERAGE(Team_Inputs!#REF!),STDEV(Team_Inputs!#REF!)),2) -> #REF! | ... R703: =ROUND(_xlfn.NORM.INV(RAND(),AVERAGE(Team_Inputs!#REF!),STDEV(Team_Inputs!#REF!)),2) -> #REF! | S703: =ROUND(_xlfn.NORM.INV(RAND(),AVERAGE([1]Team_Inputs!$H$2:$H$15),STDEV([1]Team_Inputs!$H$2:$H$15)),2) -> 6.18 | T703: =ROUND(_xlfn.NORM.INV(RAND(),AVERAGE([1]Team_Inputs!$H$2:$H$15),STDEV([1]Team_Inputs!$H$2:$H$15)),2) -> 7.13 | U703: =ROUND(_xlfn.NORM.INV(RAND(),AVERAGE([1]Team_Inputs!$H$2:$H$15),STDEV([1]Team_Inputs!$H$2:$H$15)),2) -> 7.03 | V703: =ROUND(_xlfn.NORM.INV(RAND(),AVERAGE([1]Team_Inputs!$H$2:$H$15),STDEV([1]Team_Inputs!$H$2:$H$15)),2) -> 7.2 | W703: =ROUND(_xlfn.NORM.INV(RAND(),AVERAGE([1]Team_Inputs!$H$2:$H$15),STDEV([1]Team_Inputs!$H$2:$H$15)),2) -> 6.93 | X703: =ROUND(_xlfn.NORM.INV(RAND(),AVERAGE([1]Team_Inputs!$H$2:$H$15),STDEV([1]Team_Inputs!$H$2:$H$15)),2) -> 6.78 | Y703: =ROUND(_xlfn.NORM.INV(RAND(),AVERAGE([1]Team_Inputs!$H$2:$H$15),STDEV([1]Team_Inputs!$H$2:$H$15)),2) -> 7.24 | Z703: =ROUND(_xlfn.NORM.INV(RAND(),AVERAGE([1]Team_Inputs!$H$2:$H$15),STDEV([1]Team_Inputs!$H$2:$H$15)),2) -> 6.54 | ... AC703: =ROUND(_xlfn.NORM.INV(RAND(),AVERAGE([1]Team_Inputs!$H$2:$H$15),STDEV([1]Team_Inputs!$H$2:$H$15)),2) -> 7.19
A704: Fenerbahçe | B704: Beşiktaş | C704: Away | D704: 3-5-2 | E704: 3-1-4-2 | H704: =ROUND(_xlfn.NORM.INV(RAND(),AVERAGE(Team_Inputs!#REF!),STDEV(Team_Inputs!#REF!)),2) -> #REF! | I704: =ROUND(_xlfn.NORM.INV(RAND(),AVERAGE(Team_Inputs!#REF!),STDEV(Team_Inputs!#REF!)),2) -> #REF! | J704: =ROUND(_xlfn.NORM.INV(RAND(),AVERAGE(Team_Inputs!#REF!),STDEV(Team_Inputs!#REF!)),2) -> #REF! | K704: =ROUND(_xlfn.NORM.INV(RAND(),AVERAGE(Team_Inputs!#REF!),STDEV(Team_Inputs!#REF!)),2) -> #REF! | L704: =ROUND(_xlfn.NORM.INV(RAND(),AVERAGE(Team_Inputs!#REF!),STDEV(Team_Inputs!#REF!)),2) -> #REF! | M704: =ROUND(_xlfn.NORM.INV(RAND(),AVERAGE(Team_Inputs!#REF!),STDEV(Team_Inputs!#REF!)),2) -> #REF! | N704: =ROUND(_xlfn.NORM.INV(RAND(),AVERAGE(Team_Inputs!#REF!),STDEV(Team_Inputs!#REF!)),2) -> #REF! | O704: =ROUND(_xlfn.NORM.INV(RAND(),AVERAGE(Team_Inputs!#REF!),STDEV(Team_Inputs!#REF!)),2) -> #REF! | ... R704: =ROUND(_xlfn.NORM.INV(RAND(),AVERAGE(Team_Inputs!#REF!),STDEV(Team_Inputs!#REF!)),2) -> #REF! | S704: =ROUND(_xlfn.NORM.INV(RAND(),AVERAGE([1]Team_Inputs!$H$2:$H$15),STDEV([1]Team_Inputs!$H$2:$H$15)),2) -> 6.51 | T704: =ROUND(_xlfn.NORM.INV(RAND(),AVERAGE([1]Team_Inputs!$H$2:$H$15),STDEV([1]Team_Inputs!$H$2:$H$15)),2) -> 6.4 | U704: =ROUND(_xlfn.NORM.INV(RAND(),AVERAGE([1]Team_Inputs!$H$2:$H$15),STDEV([1]Team_Inputs!$H$2:$H$15)),2) -> 7.79 | V704: =ROUND(_xlfn.NORM.INV(RAND(),AVERAGE([1]Team_Inputs!$H$2:$H$15),STDEV([1]Team_Inputs!$H$2:$H$15)),2) -> 7 | W704: =ROUND(_xlfn.NORM.INV(RAND(),AVERAGE([1]Team_Inputs!$H$2:$H$15),STDEV([1]Team_Inputs!$H$2:$H$15)),2) -> 6.92 | X704: =ROUND(_xlfn.NORM.INV(RAND(),AVERAGE([1]Team_Inputs!$H$2:$H$15),STDEV([1]Team_Inputs!$H$2:$H$15)),2) -> 6.55 | Y704: =ROUND(_xlfn.NORM.INV(RAND(),AVERAGE([1]Team_Inputs!$H$2:$H$15),STDEV([1]Team_Inputs!$H$2:$H$15)),2) -> 6.26 | Z704: =ROUND(_xlfn.NORM.INV(RAND(),AVERAGE([1]Team_Inputs!$H$2:$H$15),STDEV([1]Team_Inputs!$H$2:$H$15)),2) -> 6.78 | ... AC704: =ROUND(_xlfn.NORM.INV(RAND(),AVERAGE([1]Team_Inputs!$H$2:$H$15),STDEV([1]Team_Inputs!$H$2:$H$15)),2) -> 6.57
A705: Fenerbahçe | B705: Beşiktaş | C705: Away | D705: 3-5-2 | E705: 3-1-4-2 | H705: =ROUND(_xlfn.NORM.INV(RAND(),AVERAGE(Team_Inputs!#REF!),STDEV(Team_Inputs!#REF!)),2) -> #REF! | I705: =ROUND(_xlfn.NORM.INV(RAND(),AVERAGE(Team_Inputs!#REF!),STDEV(Team_Inputs!#REF!)),2) -> #REF! | J705: =ROUND(_xlfn.NORM.INV(RAND(),AVERAGE(Team_Inputs!#REF!),STDEV(Team_Inputs!#REF!)),2) -> #REF! | K705: =ROUND(_xlfn.NORM.INV(RAND(),AVERAGE(Team_Inputs!#REF!),STDEV(Team_Inputs!#REF!)),2) -> #REF! | L705: =ROUND(_xlfn.NORM.INV(RAND(),AVERAGE(Team_Inputs!#REF!),STDEV(Team_Inputs!#REF!)),2) -> #REF! | M705: =ROUND(_xlfn.NORM.INV(RAND(),AVERAGE(Team_Inputs!#REF!),STDEV(Team_Inputs!#REF!)),2) -> #REF! | N705: =ROUND(_xlfn.NORM.INV(RAND(),AVERAGE(Team_Inputs!#REF!),STDEV(Team_Inputs!#REF!)),2) -> #REF! | O705: =ROUND(_xlfn.NORM.INV(RAND(),AVERAGE(Team_Inputs!#REF!),STDEV(Team_Inputs!#REF!)),2) -> #REF! | ... R705: =ROUND(_xlfn.NORM.INV(RAND(),AVERAGE(Team_Inputs!#REF!),STDEV(Team_Inputs!#REF!)),2) -> #REF! | S705: =ROUND(_xlfn.NORM.INV(RAND(),AVERAGE([1]Team_Inputs!$H$2:$H$15),STDEV([1]Team_Inputs!$H$2:$H$15)),2) -> 7.06 | T705: =ROUND(_xlfn.NORM.INV(RAND(),AVERAGE([1]Team_Inputs!$H$2:$H$15),STDEV([1]Team_Inputs!$H$2:$H$15)),2) -> 6.56 | U705: =ROUND(_xlfn.NORM.INV(RAND(),AVERAGE([1]Team_Inputs!$H$2:$H$15),STDEV([1]Team_Inputs!$H$2:$H$15)),2) -> 6.7 | V705: =ROUND(_xlfn.NORM.INV(RAND(),AVERAGE([1]Team_Inputs!$H$2:$H$15),STDEV([1]Team_Inputs!$H$2:$H$15)),2) -> 7.26 | W705: =ROUND(_xlfn.NORM.INV(RAND(),AVERAGE([1]Team_Inputs!$H$2:$H$15),STDEV([1]Team_Inputs!$H$2:$H$15)),2) -> 5.28 | X705: =ROUND(_xlfn.NORM.INV(RAND(),AVERAGE([1]Team_Inputs!$H$2:$H$15),STDEV([1]Team_Inputs!$H$2:$H$15)),2) -> 6.59 | Y705: =ROUND(_xlfn.NORM.INV(RAND(),AVERAGE([1]Team_Inputs!$H$2:$H$15),STDEV([1]Team_Inputs!$H$2:$H$15)),2) -> 6.22 | Z705: =ROUND(_xlfn.NORM.INV(RAND(),AVERAGE([1]Team_Inputs!$H$2:$H$15),STDEV([1]Team_Inputs!$H$2:$H$15)),2) -> 8.02 | ... AC705: =ROUND(_xlfn.NORM.INV(RAND(),AVERAGE([1]Team_Inputs!$H$2:$H$15),STDEV([1]Team_Inputs!$H$2:$H$15)),2) -> 6.3
A706: Fenerbahçe | B706: Beşiktaş | C706: Away | D706: 3-5-2 | E706: 3-1-4-2 | H706: =ROUND(_xlfn.NORM.INV(RAND(),AVERAGE(Team_Inputs!#REF!),STDEV(Team_Inputs!#REF!)),2) -> #REF! | I706: =ROUND(_xlfn.NORM.INV(RAND(),AVERAGE(Team_Inputs!#REF!),STDEV(Team_Inputs!#REF!)),2) -> #REF! | J706: =ROUND(_xlfn.NORM.INV(RAND(),AVERAGE(Team_Inputs!#REF!),STDEV(Team_Inputs!#REF!)),2) -> #REF! | K706: =ROUND(_xlfn.NORM.INV(RAND(),AVERAGE(Team_Inputs!#REF!),STDEV(Team_Inputs!#REF!)),2) -> #REF! | L706: =ROUND(_xlfn.NORM.INV(RAND(),AVERAGE(Team_Inputs!#REF!),STDEV(Team_Inputs!#REF!)),2) -> #REF! | M706: =ROUND(_xlfn.NORM.INV(RAND(),AVERAGE(Team_Inputs!#REF!),STDEV(Team_Inputs!#REF!)),2) -> #REF! | N706: =ROUND(_xlfn.NORM.INV(RAND(),AVERAGE(Team_Inputs!#REF!),STDEV(Team_Inputs!#REF!)),2) -> #REF! | O706: =ROUND(_xlfn.NORM.INV(RAND(),AVERAGE(Team_Inputs!#REF!),STDEV(Team_Inputs!#REF!)),2) -> #REF! | ... R706: =ROUND(_xlfn.NORM.INV(RAND(),AVERAGE(Team_Inputs!#REF!),STDEV(Team_Inputs!#REF!)),2) -> #REF! | S706: =ROUND(_xlfn.NORM.INV(RAND(),AVERAGE([1]Team_Inputs!$H$2:$H$15),STDEV([1]Team_Inputs!$H$2:$H$15)),2) -> 7.02 | T706: =ROUND(_xlfn.NORM.INV(RAND(),AVERAGE([1]Team_Inputs!$H$2:$H$15),STDEV([1]Team_Inputs!$H$2:$H$15)),2) -> 6.57 | U706: =ROUND(_xlfn.NORM.INV(RAND(),AVERAGE([1]Team_Inputs!$H$2:$H$15),STDEV([1]Team_Inputs!$H$2:$H$15)),2) -> 7.33 | V706: =ROUND(_xlfn.NORM.INV(RAND(),AVERAGE([1]Team_Inputs!$H$2:$H$15),STDEV([1]Team_Inputs!$H$2:$H$15)),2) -> 7.16 | W706: =ROUND(_xlfn.NORM.INV(RAND(),AVERAGE([1]Team_Inputs!$H$2:$H$15),STDEV([1]Team_Inputs!$H$2:$H$15)),2) -> 6.42 | X706: =ROUND(_xlfn.NORM.INV(RAND(),AVERAGE([1]Team_Inputs!$H$2:$H$15),STDEV([1]Team_Inputs!$H$2:$H$15)),2) -> 6.07 | Y706: =ROUND(_xlfn.NORM.INV(RAND(),AVERAGE([1]Team_Inputs!$H$2:$H$15),STDEV([1]Team_Inputs!$H$2:$H$15)),2) -> 6.47 | Z706: =ROUND(_xlfn.NORM.INV(RAND(),AVERAGE([1]Team_Inputs!$H$2:$H$15),STDEV([1]Team_Inputs!$H$2:$H$15)),2) -> 7.91 | ... AC706: =ROUND(_xlfn.NORM.INV(RAND(),AVERAGE([1]Team_Inputs!$H$2:$H$15),STDEV([1]Team_Inputs!$H$2:$H$15)),2) -> 5.75
A707: Fenerbahçe | B707: Beşiktaş | C707: Away | D707: 3-5-2 | E707: 3-1-4-2 | H707: =ROUND(_xlfn.NORM.INV(RAND(),AVERAGE(Team_Inputs!#REF!),STDEV(Team_Inputs!#REF!)),2) -> #REF! | I707: =ROUND(_xlfn.NORM.INV(RAND(),AVERAGE(Team_Inputs!#REF!),STDEV(Team_Inputs!#REF!)),2) -> #REF! | J707: =ROUND(_xlfn.NORM.INV(RAND(),AVERAGE(Team_Inputs!#REF!),STDEV(Team_Inputs!#REF!)),2) -> #REF! | K707: =ROUND(_xlfn.NORM.INV(RAND(),AVERAGE(Team_Inputs!#REF!),STDEV(Team_Inputs!#REF!)),2) -> #REF! | L707: =ROUND(_xlfn.NORM.INV(RAND(),AVERAGE(Team_Inputs!#REF!),STDEV(Team_Inputs!#REF!)),2) -> #REF! | M707: =ROUND(_xlfn.NORM.INV(RAND(),AVERAGE(Team_Inputs!#REF!),STDEV(Team_Inputs!#REF!)),2) -> #REF! | N707: =ROUND(_xlfn.NORM.INV(RAND(),AVERAGE(Team_Inputs!#REF!),STDEV(Team_Inputs!#REF!)),2) -> #REF! | O707: =ROUND(_xlfn.NORM.INV(RAND(),AVERAGE(Team_Inputs!#REF!),STDEV(Team_Inputs!#REF!)),2) -> #REF! | ... R707: =ROUND(_xlfn.NORM.INV(RAND(),AVERAGE(Team_Inputs!#REF!),STDEV(Team_Inputs!#REF!)),2) -> #REF! | S707: =ROUND(_xlfn.NORM.INV(RAND(),AVERAGE([1]Team_Inputs!$H$2:$H$15),STDEV([1]Team_Inputs!$H$2:$H$15)),2) -> 6.1 | T707: =ROUND(_xlfn.NORM.INV(RAND(),AVERAGE([1]Team_Inputs!$H$2:$H$15),STDEV([1]Team_Inputs!$H$2:$H$15)),2) -> 6.06 | U707: =ROUND(_xlfn.NORM.INV(RAND(),AVERAGE([1]Team_Inputs!$H$2:$H$15),STDEV([1]Team_Inputs!$H$2:$H$15)),2) -> 6.42 | V707: =ROUND(_xlfn.NORM.INV(RAND(),AVERAGE([1]Team_Inputs!$H$2:$H$15),STDEV([1]Team_Inputs!$H$2:$H$15)),2) -> 6.04 | W707: =ROUND(_xlfn.NORM.INV(RAND(),AVERAGE([1]Team_Inputs!$H$2:$H$15),STDEV([1]Team_Inputs!$H$2:$H$15)),2) -> 6.38 | X707: =ROUND(_xlfn.NORM.INV(RAND(),AVERAGE([1]Team_Inputs!$H$2:$H$15),STDEV([1]Team_Inputs!$H$2:$H$15)),2) -> 6.64 | Y707: =ROUND(_xlfn.NORM.INV(RAND(),AVERAGE([1]Team_Inputs!$H$2:$H$15),STDEV([1]Team_Inputs!$H$2:$H$15)),2) -> 6.68 | Z707: =ROUND(_xlfn.NORM.INV(RAND(),AVERAGE([1]Team_Inputs!$H$2:$H$15),STDEV([1]Team_Inputs!$H$2:$H$15)),2) -> 6.4 | ... AC707: =ROUND(_xlfn.NORM.INV(RAND(),AVERAGE([1]Team_Inputs!$H$2:$H$15),STDEV([1]Team_Inputs!$H$2:$H$15)),2) -> 7.09
